Workbook
Name Z_DAF976D5_FCCB_4417_8719_3CCA499BF400_.wvu.Cols: ABR!$K:$K,ABR!$T:$T,ABR!$W:$W,ABR!#REF!
Name Z_DAF976D5_FCCB_4417_8719_3CCA499BF400_.wvu.Cols: AGO!$K:$K,AGO!$T:$T,AGO!$W:$W,AGO!#REF!
Name Z_DAF976D5_FCCB_4417_8719_3CCA499BF400_.wvu.Cols: DIC!$K:$K,DIC!$T:$T,DIC!$W:$W,DIC!#REF!
Name Z_DAF976D5_FCCB_4417_8719_3CCA499BF400_.wvu.Cols: ENE!$K:$K,ENE!$T:$T,ENE!$W:$W,ENE!#REF!
Name Z_DAF976D5_FCCB_4417_8719_3CCA499BF400_.wvu.Cols: FEB!$K:$K,FEB!$T:$T,FEB!$W:$W,FEB!#REF!
Name Z_DAF976D5_FCCB_4417_8719_3CCA499BF400_.wvu.Cols: JUL!$K:$K,JUL!$T:$T,JUL!$W:$W,JUL!#REF!
Name Z_DAF976D5_FCCB_4417_8719_3CCA499BF400_.wvu.Cols: JUN!$K:$K,JUN!$T:$T,JUN!$W:$W,JUN!#REF!
Name Z_DAF976D5_FCCB_4417_8719_3CCA499BF400_.wvu.Cols: MAR!$K:$K,MAR!$T:$T,MAR!$W:$W,MAR!#REF!
Name Z_DAF976D5_FCCB_4417_8719_3CCA499BF400_.wvu.Cols: MAY!$K:$K,MAY!$T:$T,MAY!$W:$W,MAY!#REF!
Name Z_DAF976D5_FCCB_4417_8719_3CCA499BF400_.wvu.Cols: Modelo!$K:$K,Modelo!$P:$P,Modelo!$R:$R,Modelo!#REF!
Name Z_DAF976D5_FCCB_4417_8719_3CCA499BF400_.wvu.Cols: NOV!$K:$K,NOV!$T:$T,NOV!$W:$W,NOV!#REF!
Name Z_DAF976D5_FCCB_4417_8719_3CCA499BF400_.wvu.Cols: OCT!$K:$K,OCT!$T:$T,OCT!$W:$W,OCT!#REF!
Name Z_DAF976D5_FCCB_4417_8719_3CCA499BF400_.wvu.Cols: SEP!$K:$K,SEP!$T:$T,SEP!$W:$W,SEP!#REF!

Sheet ENE
B1: Producción | AH1: Extracción | AN1: Indicadores
C2: 50 | D2: 25 | E2: 10 | F2: 50 | G2: 25 | H2: 50 | I2: 25 | J2: 25 | K2: 50 | L2: 25 | Q2: 50 | R2: 1 | S2: 1 | T2: 1 | U2: 25 | X2: 25 | Y2: 25 | Z2: 25 | AA2: 25 | AB2: 40 | AC2: 50
B3: HARINA EN BULTO | R3: HARINA GRANEL | U3: P. EXP | V3: REPASO | X3: ESPECIAL | AA3: SUBPRODUCTO | AF3: EXTRACION | AN3: HORAS | AQ3: INDICACORES MOLINO | AV3: MOJADORA | AW3: EQUIPOS ELECTRONICOS
A4: Dia | B4: Fecha | C4: Extrapan 50 | D4: Extrapan 25 | E4: Extrapan 10 | F4: Artesanal 50 | G4: Artesanal 25 | H4: Natural 50 | I4: Fuerte 25 | J4: Fuerte exp 25 | K4: Exclusiva 50 | L4: Exclusiva 25 | M4: S. Sal 25 | N4: Harina Tortas y Ponques | O4: Harina Galeras Ligera | P4: H. Manitova | Q4: ESPECIAL 50 | R4: Harina de alta proteina x 1 G | S4: Harina de baja proteina x 1 | T4: ARTESANAL X 1 G | U4: H. espcial x 25 | V4: + Repaso | W4: - Reproceso | X4: Germen 25 | Y4: Semola 25 | Z4: Grano entero 25 | AA4: Salvado 25 | AB4: Mogolla 40 | AC4: Segunda 50 | AD4: Total trigo | AE4: Total Bultos | AF4: Harina | AG4: Grano entero partido | AH4: =X4 -> Germen 25 | AI4: Semola | AJ4: =AA4 -> Salvado 25 | AK4: =AB4 -> Mogolla 40 | AL4: =AC4 -> Segunda 50 | AM4: =B4 -> Fecha | AN4: Molienda | AO4: moje | AP4: Horas varada | AQ4: Molido/ Mojado | AR4: Capacidad TM. hora | AS4: Capacidad TM. Día | AT4: % Utilizado | AU4: Bultos Hora | AV4: capacidad TM. hora | AW4: MYFC | AX4: Bascula Trigo | AY4: Bascula Harina | AZ4: Agua M³ | BA4: Bascula Mejorante A | BB4: Bascula Mejorante B | BC4: Flowbalacer 1 | BD4: Flowbalacer 2 | BE4: Flowbalacer 3 | BF4: Flowbalacer 4
A5: 1 | B5: 46027 | R5: 40672 | S5: 37488 | AA5: =97+50 -> 147 | AB5: =138+152 -> 290 | AC5: =86+50 -> 136 | AD5: =+IF(B5="","",SUMPRODUCT(C5:AC5,$C$2:$AC$2)) -> 100235 | AE5: =IF(B5="","",C5+F5+H5+K5+Q5+N5+O5+((I5+J5+D5+G5)/2)+(R5/50)+(S5/50)+(T5/50)+(U5/2)+(E5/5)) -> 1563.2 | AF5: =IF(B5="","",((AE5*50)/AD5)) -> 0.77976755 | AG5: =IF(C5="","",((Z5)*25)/AD5) | AH5: =IF(B5="","",(X5*25)/AD5) -> 0 | AI5: =IF(B5="","",(Y5*25)/AD5) -> 0 | AJ5: =IF(B5="","",(AA5*25)/AD5) -> 0.03666384 | AK5: =IF(B5="","",(AB5*40)/AD5) -> 0.11572804 | AL5: =IF(B5="","",(AC5*50)/AD5) -> 0.067840575 | AM5: =IF(B5="","",B5) -> 46027 | AN5: 18 | AO5: 16.5 | AP5: 0.25 | AQ5: =IF(AN5="","",AN5/AO5) -> 1.0909091 | AR5: =IF(AN5="","",(AD5/AN5)/1000) -> 5.5686111 | AS5: =IF(AN5="","",AR5*24) -> 133.64667 | AT5: =IF(AN5="","",(AD5/1000)*100%/AS5) -> 0.75 | AU5: =IF(AN5="","",(AE5/AN5)) -> 86.844444 | AV5: =IF(AN5="","",(AD5/AO5)/1000) -> 6.0748485 | AX5: 2031488 | AY5: 1577712 | AZ5: 68862 | BA5: 1632 | BB5: 374982 | BC5: 1540192 | BD5: 1476 | BE5: 431952 | BF5: 245848
A6: 2 | B6: 46028 | F6: 180 | I6: 909 | J6: 80 | R6: 33856 | T6: 20640 | Z6: 131 | AA6: =145+58+78 -> 281 | AB6: =133+115+139 -> 387 | AC6: =37+30 -> 67 | AD6: =+IF(B6="","",SUMPRODUCT(C6:AC6,$C$2:$AC$2)) -> 117351 | AE6: =IF(B6="","",C6+F6+H6+K6+Q6+N6+O6+((I6+J6+D6+G6+U6)/2)+(R6/50)+(S6/50)+(T6/50)+(E6/5)) -> 1764.42 | AF6: =IF(B6="","",((AE6*50)/AD6)) -> 0.75177033 | AG6: =IF(C6="","",((Z6)*25)/AD6) | AH6: =IF(B6="","",(X6*25)/AD6) -> 0 | AI6: =IF(B6="","",(Y6*25)/AD6) -> 0 | AJ6: =IF(B6="","",(AA6*25)/AD6) -> 0.059863146 | AK6: =IF(B6="","",(AB6*40)/AD6) -> 0.13191196 | AL6: =IF(B6="","",(AC6*50)/AD6) -> 0.028546838 | AM6: =IF(B6="","",B6) -> 46028 | AN6: 23 | AO6: =14.5+18.5/2 -> 23.75 | AP6: 0.33 | AQ6: =IF(AN6="","",AN6/AO6) -> 0.96842105 | AR6: =IF(AN6="","",(AD6/AN6)/1000) -> 5.1022174 | AS6: =IF(AN6="","",AR6*24) -> 122.45322 | AT6: =IF(AN6="","",(AD6/1000)*100%/AS6) -> 0.95833333 | AU6: =IF(AN6="","",(AE6/AN6)) -> 76.713913 | AV6: =IF(AN6="","",(AD6/AO6)/1000) -> 4.9410947
A7: 3 | B7: 46029 | C7: 1471 | F7: 315 | G7: 182 | AA7: 175 | AB7: 398 | AC7: 95 | AD7: =+IF(B7="","",SUMPRODUCT(C7:AC7,$C$2:$AC$2)) -> 118895 | AE7: =IF(B7="","",C7+F7+H7+K7+Q7+N7+O7+((I7+J7+D7+G7+U7)/2)+(R7/50)+(S7/50)+(T7/50)+(E7/5)) -> 1877 | AF7: =IF(B7="","",((AE7*50)/AD7)) -> 0.78935195 | AG7: =IF(C7="","",((Z7)*25)/AD7) -> 0 | AH7: =IF(B7="","",(X7*25)/AD7) -> 0 | AI7: =IF(B7="","",(Y7*25)/AD7) -> 0 | AJ7: =IF(B7="","",(AA7*25)/AD7) -> 0.036797174 | AK7: =IF(B7="","",(AB7*40)/AD7) -> 0.13389966 | AL7: =IF(B7="","",(AC7*50)/AD7) -> 0.039951217 | AM7: =IF(B7="","",B7) -> 46029 | AN7: 24 | AO7: 18.3 | AP7: 0 | AQ7: =IF(AN7="","",AN7/AO7) -> 1.3114754 | AR7: =IF(AN7="","",(AD7/AN7)/1000) -> 4.9539583 | AS7: =IF(AN7="","",AR7*24) -> 118.895 | AT7: =IF(AN7="","",(AD7/1000)*100%/AS7) -> 1 | AU7: =IF(AN7="","",(AE7/AN7)) -> 78.208333 | AV7: =IF(AN7="","",(AD7/AO7)/1000) -> 6.4969945
A8: 4 | B8: 46030 | C8: 1386 | D8: 248 | R8: 10352 | AA8: 173 | AB8: 376 | AC8: 95 | AD8: =+IF(B8="","",SUMPRODUCT(C8:AC8,$C$2:$AC$2)) -> 109967 | AE8: =IF(B8="","",C8+F8+H8+K8+Q8+N8+O8+((I8+J8+D8+G8+U8)/2)+(R8/50)+(S8/50)+(T8/50)+(E8/5)) -> 1717.04 | AF8: =IF(B8="","",((AE8*50)/AD8)) -> 0.78070694 | AG8: =IF(C8="","",((Z8)*25)/AD8) -> 0 | AH8: =IF(B8="","",(X8*25)/AD8) -> 0 | AI8: =IF(B8="","",(Y8*25)/AD8) -> 0 | AJ8: =IF(B8="","",(AA8*25)/AD8) -> 0.039329981 | AK8: =IF(B8="","",(AB8*40)/AD8) -> 0.1367683 | AL8: =IF(B8="","",(AC8*50)/AD8) -> 0.043194777 | AM8: =IF(B8="","",B8) -> 46030 | AN8: 23.75 | AO8: 14 | AP8: 0.25 | AQ8: =IF(AN8="","",AN8/AO8) -> 1.6964286 | AR8: =IF(AN8="","",(AD8/AN8)/1000) -> 4.6301895 | AS8: =IF(AN8="","",AR8*24) -> 111.12455 | AT8: =IF(AN8="","",(AD8/1000)*100%/AS8) -> 0.98958333 | AU8: =IF(AN8="","",(AE8/AN8)) -> 72.296421 | AV8: =IF(AN8="","",(AD8/AO8)/1000) -> 7.8547857
A9: 5 | B9: 46031 | R9: 38912 | S9: 49552 | Z9: 121 | AA9: 193 | AB9: 447 | AC9: 209 | AD9: =+IF(B9="","",SUMPRODUCT(C9:AC9,$C$2:$AC$2)) -> 124644 | AE9: =IF(B9="","",C9+F9+H9+K9+Q9+N9+O9+((I9+J9+D9+G9+U9)/2)+(R9/50)+(S9/50)+(T9/50)+(E9/5)) -> 1769.28 | AF9: =IF(B9="","",((AE9*50)/AD9)) -> 0.70973332 | AG9: =IF(C9="","",((Z9)*25)/AD9) | AH9: =IF(B9="","",(X9*25)/AD9) -> 0 | AI9: =IF(B9="","",(Y9*25)/AD9) -> 0 | AJ9: =IF(B9="","",(AA9*25)/AD9) -> 0.038710247 | AK9: =IF(B9="","",(AB9*40)/AD9) -> 0.14344854 | AL9: =IF(B9="","",(AC9*50)/AD9) -> 0.083838773 | AM9: =IF(B9="","",B9) -> 46031 | AN9: 24 | AO9: 14.3 | AP9: 0 | AQ9: =IF(AN9="","",AN9/AO9) -> 1.6783217 | AR9: =IF(AN9="","",(AD9/AN9)/1000) -> 5.1935 | AS9: =IF(AN9="","",AR9*24) -> 124.644 | AT9: =IF(AN9="","",(AD9/1000)*100%/AS9) -> 1 | AU9: =IF(AN9="","",(AE9/AN9)) -> 73.72 | AV9: =IF(AN9="","",(AD9/AO9)/1000) -> 8.7163636
A10: 6 | B10: 46035 | I10: 407 | R10: 104476 | AA10: 263 | AB10: 433 | AC10: 140 | AD10: =+IF(B10="","",SUMPRODUCT(C10:AC10,$C$2:$AC$2)) -> 145546 | AE10: =IF(B10="","",C10+F10+H10+K10+Q10+N10+O10+((I10+J10+D10+G10+U10)/2)+(R10/50)+(S10/50)+(T10/50)+(E10/5)) -> 2293.02 | AF10: =IF(B10="","",((AE10*50)/AD10)) -> 0.78773034 | AG10: =IF(C10="","",((Z10)*25)/AD10) | AH10: =IF(B10="","",(X10*25)/AD10) -> 0 | AI10: =IF(B10="","",(Y10*25)/AD10) -> 0 | AJ10: =IF(B10="","",(AA10*25)/AD10) -> 0.045174721 | AK10: =IF(B10="","",(AB10*40)/AD10) -> 0.11900018 | AL10: =IF(B10="","",(AC10*50)/AD10) -> 0.04809476 | AM10: =IF(B10="","",B10) -> 46035 | AN10: 23.5 | AO10: =5.25+15.5 -> 20.75 | AP10: 0.5 | AQ10: =IF(AN10="","",AN10/AO10) -> 1.1325301 | AR10: =IF(AN10="","",(AD10/AN10)/1000) -> 6.1934468 | AS10: =IF(AN10="","",AR10*24) -> 148.64272 | AT10: =IF(AN10="","",(AD10/1000)*100%/AS10) -> 0.97916667 | AU10: =IF(AN10="","",(AE10/AN10)) -> 97.575319 | AV10: =IF(AN10="","",(AD10/AO10)/1000) -> 7.0142651
A11: 7 | B11: 46036 | C11: 552 | D11: 1000 | I11: 611 | K11: 746 | Y11: 10 | AA11: 137 | AB11: 403 | AC11: 90 | AD11: =+IF(B11="","",SUMPRODUCT(C11:AC11,$C$2:$AC$2)) -> 129470 | AE11: =IF(B11="","",C11+F11+H11+K11+Q11+N11+O11+((I11+J11+D11+G11+U11)/2)+(R11/50)+(S11/50)+(T11/50)+(E11/5)) -> 2103.5 | AF11: =IF(B11="","",((AE11*50)/AD11)) -> 0.81235035 | AG11: =IF(C11="","",((Z11)*25)/AD11) -> 0 | AH11: =IF(B11="","",(X11*25)/AD11) -> 0 | AI11: =IF(B11="","",(Y11*25)/AD11) -> 0.0019309493 | AJ11: =IF(B11="","",(AA11*25)/AD11) -> 0.026454005 | AK11: =IF(B11="","",(AB11*40)/AD11) -> 0.12450761 | AL11: =IF(B11="","",(AC11*50)/AD11) -> 0.034757087 | AM11: =IF(B11="","",B11) -> 46036 | AN11: 23.5 | AO11: 18.5 | AP11: 0.5 | AQ11: =IF(AN11="","",AN11/AO11) -> 1.2702703 | AR11: =IF(AN11="","",(AD11/AN11)/1000) -> 5.5093617 | AS11: =IF(AN11="","",AR11*24) -> 132.22468 | AT11: =IF(AN11="","",(AD11/1000)*100%/AS11) -> 0.97916667 | AU11: =IF(AN11="","",(AE11/AN11)) -> 89.510638 | AV11: =IF(AN11="","",(AD11/AO11)/1000) -> 6.9983784
A12: 8 | B12: 46037 | C12: 505 | R12: 64528 | Y12: 15 | AA12: 147 | AB12: 364 | AC12: 131 | AD12: =+IF(B12="","",SUMPRODUCT(C12:AC12,$C$2:$AC$2)) -> 114938 | AE12: =IF(B12="","",C12+F12+H12+K12+Q12+N12+O12+((I12+J12+D12+G12+U12)/2)+(R12/50)+(S12/50)+(T12/50)+(E12/5)) -> 1795.56 | AF12: =IF(B12="","",((AE12*50)/AD12)) -> 0.78109938 | AG12: =IF(C12="","",((Z12)*25)/AD12) -> 0 | AH12: =IF(B12="","",(X12*25)/AD12) -> 0 | AI12: =IF(B12="","",(Y12*25)/AD12) -> 0.0032626285 | AJ12: =IF(B12="","",(AA12*25)/AD12) -> 0.03197376 | AK12: =IF(B12="","",(AB12*40)/AD12) -> 0.12667699 | AL12: =IF(B12="","",(AC12*50)/AD12) -> 0.056987245 | AM12: =IF(B12="","",B12) -> 46037 | AN12: 24 | AO12: 12 | AP12: 0 | AQ12: =IF(AN12="","",AN12/AO12) -> 2 | AR12: =IF(AN12="","",(AD12/AN12)/1000) -> 4.7890833 | AS12: =IF(AN12="","",AR12*24) -> 114.938 | AT12: =IF(AN12="","",(AD12/1000)*100%/AS12) -> 1 | AU12: =IF(AN12="","",(AE12/AN12)) -> 74.815 | AV12: =IF(AN12="","",(AD12/AO12)/1000) -> 9.5781667
A13: 9 | B13: 46038 | R13: 39760 | S13: 44536 | U13: 200 | AA13: 191 | AB13: 457 | AC13: 88 | AD13: =+IF(B13="","",SUMPRODUCT(C13:AC13,$C$2:$AC$2)) -> 116751 | AE13: =IF(B13="","",C13+F13+H13+K13+Q13+N13+O13+((I13+J13+D13+G13+U13)/2)+(R13/50)+(S13/50)+(T13/50)+(E13/5)) -> 1785.92 | AF13: =IF(B13="","",((AE13*50)/AD13)) -> 0.76484141 | AG13: =IF(C13="","",((Z13)*25)/AD13) | AH13: =IF(B13="","",(X13*25)/AD13) -> 0 | AI13: =IF(B13="","",(Y13*25)/AD13) -> 0 | AJ13: =IF(B13="","",(AA13*25)/AD13) -> 0.040899007 | AK13: =IF(B13="","",(AB13*40)/AD13) -> 0.15657253 | AL13: =IF(B13="","",(AC13*50)/AD13) -> 0.037687043 | AM13: =IF(B13="","",B13) -> 46038 | AN13: 23.75 | AO13: 14.9 | AP13: 0.25 | AQ13: =IF(AN13="","",AN13/AO13) -> 1.5939597 | AR13: =IF(AN13="","",(AD13/AN13)/1000) -> 4.9158316 | AS13: =IF(AN13="","",AR13*24) -> 117.97996 | AT13: =IF(AN13="","",(AD13/1000)*100%/AS13) -> 0.98958333 | AU13: =IF(AN13="","",(AE13/AN13)) -> 75.196632 | AV13: =IF(AN13="","",(AD13/AO13)/1000) -> 7.8356376
A14: 10 | B14: 46041 | R14: 100080 | Y14: 10 | AA14: 179 | AB14: 406 | AC14: 127 | AD14: =+IF(B14="","",SUMPRODUCT(C14:AC14,$C$2:$AC$2)) -> 127395 | AE14: =IF(B14="","",C14+F14+H14+K14+Q14+N14+O14+((I14+J14+D14+G14+U14)/2)+(R14/50)+(S14/50)+(T14/50)+(E14/5)) -> 2001.6 | AF14: =IF(B14="","",((AE14*50)/AD14)) -> 0.78558813 | AG14: =IF(C14="","",((Z14)*25)/AD14) | AH14: =IF(B14="","",(X14*25)/AD14) -> 0 | AI14: =IF(B14="","",(Y14*25)/AD14) -> 0.0019624004 | AJ14: =IF(B14="","",(AA14*25)/AD14) -> 0.035126967 | AK14: =IF(B14="","",(AB14*40)/AD14) -> 0.12747753 | AL14: =IF(B14="","",(AC14*50)/AD14) -> 0.04984497 | AM14: =IF(B14="","",B14) -> 46041 | AN14: 24 | AO14: =9.1+14.75 -> 23.85 | AP14: 0 | AQ14: =IF(AN14="","",AN14/AO14) -> 1.0062893 | AR14: =IF(AN14="","",(AD14/AN14)/1000) -> 5.308125 | AS14: =IF(AN14="","",AR14*24) -> 127.395 | AT14: =IF(AN14="","",(AD14/1000)*100%/AS14) -> 1 | AU14: =IF(AN14="","",(AE14/AN14)) -> 83.4 | AV14: =IF(AN14="","",(AD14/AO14)/1000) -> 5.3415094
A15: 11 | B15: 46042 | C15: 1100 | R15: 3328 | S15: 24560 | Y15: 31 | AA15: 138 | AB15: 416 | AC15: 81 | AD15: =+IF(B15="","",SUMPRODUCT(C15:AC15,$C$2:$AC$2)) -> 107803 | AE15: =IF(B15="","",C15+F15+H15+K15+Q15+N15+O15+((I15+J15+D15+G15+U15)/2)+(R15/50)+(S15/50)+(T15/50)+(E15/5)) -> 1657.76 | AF15: =IF(B15="","",((AE15*50)/AD15)) -> 0.76888398 | AG15: =IF(C15="","",((Z15)*25)/AD15) -> 0 | AH15: =IF(B15="","",(X15*25)/AD15) -> 0 | AI15: =IF(B15="","",(Y15*25)/AD15) -> 0.0071890393 | AJ15: =IF(B15="","",(AA15*25)/AD15) -> 0.03200282 | AK15: =IF(B15="","",(AB15*40)/AD15) -> 0.15435563 | AL15: =IF(B15="","",(AC15*50)/AD15) -> 0.037568528 | AM15: =IF(B15="","",B15) -> 46042 | AN15: 24 | AO15: 22.25 | AP15: 0 | AQ15: =IF(AN15="","",AN15/AO15) -> 1.0786517 | AR15: =IF(AN15="","",(AD15/AN15)/1000) -> 4.4917917 | AS15: =IF(AN15="","",AR15*24) -> 107.803 | AT15: =IF(AN15="","",(AD15/1000)*100%/AS15) -> 1 | AU15: =IF(AN15="","",(AE15/AN15)) -> 69.073333 | AV15: =IF(AN15="","",(AD15/AO15)/1000) -> 4.8450787
A16: 12 | B16: 46043 | C16: 792 | F16: 346 | G16: 300 | I16: 826 | J16: 120 | Y16: 19 | AA16: 160 | AB16: 390 | AC16: 98 | AD16: =+IF(B16="","",SUMPRODUCT(C16:AC16,$C$2:$AC$2)) -> 113025 | AE16: =IF(B16="","",C16+F16+H16+K16+Q16+N16+O16+((I16+J16+D16+G16+U16)/2)+(R16/50)+(S16/50)+(T16/50)+(E16/5)) -> 1761 | AF16: =IF(B16="","",((AE16*50)/AD16)) -> 0.77903119 | AG16: =IF(C16="","",((Z16)*25)/AD16) -> 0 | AH16: =IF(B16="","",(X16*25)/AD16) -> 0 | AI16: =IF(B16="","",(Y16*25)/AD16) -> 0.00420261 | AJ16: =IF(B16="","",(AA16*25)/AD16) -> 0.0353904 | AK16: =IF(B16="","",(AC16*40)/AD16) -> 0.034682592 | AL16: =IF(B16="","",(AC16*50)/AD16) -> 0.04335324 | AM16: =IF(B16="","",B16) -> 46043 | AN16: 24 | AO16: 14.9 | AP16: 0 | AQ16: =IF(AN16="","",AN16/AO16) -> 1.6107383 | AR16: =IF(AN16="","",(AD16/AN16)/1000) -> 4.709375 | AS16: =IF(AN16="","",AR16*24) -> 113.025 | AT16: =IF(AN16="","",(AD16/1000)*100%/AS16) -> 1 | AU16: =IF(AN16="","",(AE16/AN16)) -> 73.375 | AV16: =IF(AN16="","",(AD16/AO16)/1000) -> 7.5855705
A17: 13 | B17: 46044 | C17: 1718 | Q17: 30 | AA17: 156 | AB17: 379 | AC17: 59 | AD17: =+IF(B17="","",SUMPRODUCT(C17:AC17,$C$2:$AC$2)) -> 109410 | AE17: =IF(B17="","",C17+F17+H17+K17+Q17+N17+O17+((I17+J17+D17+G17+U17)/2)+(R17/50)+(S17/50)+(T17/50)+(E17/5)) -> 1748 | AF17: =IF(B17="","",((AE17*50)/AD17)) -> 0.79883009 | AG17: =IF(C17="","",((Z17)*25)/AD17) -> 0 | AH17: =IF(B17="","",(X17*25)/AD17) -> 0 | AI17: =IF(B17="","",(Y17*25)/AD17) -> 0 | AJ17: =IF(B17="","",(AA17*25)/AD17) -> 0.035645736 | AK17: =IF(B17="","",(AB17*40)/AD17) -> 0.13856137 | AL17: =IF(B17="","",(AC17*50)/AD17) -> 0.0269628 | AM17: =IF(B17="","",B17) -> 46044 | AN17: 23 | AO17: 19.25 | AP17: 1 | AQ17: =IF(AN17="","",AN17/AO17) -> 1.1948052 | AR17: =IF(AN17="","",(AD17/AN17)/1000) -> 4.7569565 | AS17: =IF(AN17="","",AR17*24) -> 114.16696 | AT17: =IF(AN17="","",(AD17/1000)*100%/AS17) -> 0.95833333 | AU17: =IF(AN17="","",(AE17/AN17)) -> 76 | AV17: =IF(AN17="","",(AD17/AO17)/1000) -> 5.6836364
A18: 14 | B18: 46045 | Q18: 235 | R18: 57552 | S18: 7850 | X18: 15 | Z18: 103 | AA18: 181 | AB18: 364 | AC18: 158 | AD18: =+IF(B18="","",SUMPRODUCT(C18:AC18,$C$2:$AC$2)) -> 107087 | AE18: =IF(B18="","",C18+F18+H18+K18+Q18+N18+O18+((I18+J18+D18+G18+U18)/2)+(R18/50)+(S18/50)+(T18/50)+(E18/5)) -> 1543.04 | AF18: =IF(B18="","",((AE18*50)/AD18)) -> 0.72046093 | AG18: =IF(C18="","",((Z18)*25)/AD18) | AH18: =IF(B18="","",(X18*25)/AD18) -> 0.0035018256 | AI18: =IF(B18="","",(Y18*25)/AD18) -> 0 | AJ18: =IF(B18="","",(AA18*25)/AD18) -> 0.042255362 | AK18: =IF(B18="","",(AB18*40)/AD18) -> 0.13596422 | AL18: =IF(B18="","",(AC18*50)/AD18) -> 0.073771793 | AM18: =IF(B18="","",B18) -> 46045 | AN18: 21.7 | AO18: 19.1 | AP18: 2.28 | AQ18: =IF(AN18="","",AN18/AO18) -> 1.1361257 | AR18: =IF(AN18="","",(AD18/AN18)/1000) -> 4.9348848 | AS18: =IF(AN18="","",AR18*24) -> 118.43724 | AT18: =IF(AN18="","",(AD18/1000)*100%/AS18) -> 0.90416667 | AU18: =IF(AN18="","",(AE18/AN18)) -> 71.107834 | AV18: =IF(AN18="","",(AD18/AO18)/1000) -> 5.6066492
A19: 15 | B19: 46050 | C19: 581 | F19: 317 | G19: 300 | H19: 488 | S19: 24736 | AA19: 220 | AB19: 484 | AC19: 43 | AD19: =+IF(B19="","",SUMPRODUCT(C19:AC19,$C$2:$AC$2)) -> 128546 | AE19: =IF(B19="","",C19+F19+H19+K19+Q19+N19+O19+((I19+J19+D19+G19+U19)/2)+(R19/50)+(S19/50)+(T19/50)+(E19/5)) -> 2030.72 | AF19: =IF(B19="","",((AE19*50)/AD19)) -> 0.78988067 | AG19: =IF(C19="","",((Z19)*25)/AD19) -> 0 | AH19: =IF(B19="","",(X19*25)/AD19) -> 0 | AI19: =IF(B19="","",(Y19*25)/AD19) -> 0 | AJ19: =IF(B19="","",(AA19*25)/AD19) -> 0.04278624 | AK19: =IF(B19="","",(AB19*40)/AD19) -> 0.15060756 | AL19: =IF(B19="","",(AC19*50)/AD19) -> 0.01672553 | AM19: =IF(B19="","",B19) -> 46050 | AN19: 23.58 | AO19: =17.5+1.5 -> 19 | AP19: 0.41 | AQ19: =IF(AN19="","",AN19/AO19) -> 1.2410526 | AR19: =IF(AN19="","",(AD19/AN19)/1000) -> 5.4514843 | AS19: =IF(AN19="","",AR19*24) -> 130.83562 | AT19: =IF(AN19="","",(AD19/1000)*100%/AS19) -> 0.9825 | AU19: =IF(AN19="","",(AE19/AN19)) -> 86.120441 | AV19: =IF(AN19="","",(AD19/AO19)/1000) -> 6.7655789
A20: 16 | B20: 46051 | C20: 1892 | Z20: 23 | AA20: 160 | AB20: 403 | AC20: 71 | AD20: =+IF(B20="","",SUMPRODUCT(C20:AC20,$C$2:$AC$2)) -> 118845 | AE20: =IF(B20="","",C20+F20+H20+K20+Q20+N20+O20+((I20+J20+D20+G20+U20)/2)+(R20/50)+(S20/50)+(T20/50)+(E20/5)) -> 1892 | AF20: =IF(B20="","",((AE20*50)/AD20)) -> 0.79599478 | AG20: =IF(C20="","",((Z20)*25)/AD20) -> 0.0048382347 | AH20: =IF(B20="","",(X20*25)/AD20) -> 0 | AI20: =IF(B20="","",(Y20*25)/AD20) -> 0 | AJ20: =IF(B20="","",(AA20*25)/AD20) -> 0.033657285 | AK20: =IF(B20="","",(AB20*40)/AD20) -> 0.13563886 | AL20: =IF(B20="","",(AC20*50)/AD20) -> 0.02987084 | AM20: =IF(B20="","",B20) -> 46051 | AN20: 23.67 | AO20: 18.9 | AP20: 0.33 | AQ20: =IF(AN20="","",AN20/AO20) -> 1.252381 | AR20: =IF(AN20="","",(AD20/AN20)/1000) -> 5.0209125 | AS20: =IF(AN20="","",AR20*24) -> 120.5019 | AT20: =IF(AN20="","",(AD20/1000)*100%/AS20) -> 0.98625 | AU20: =IF(AN20="","",(AE20/AN20)) -> 79.932404 | AV20: =IF(AN20="","",(AD20/AO20)/1000) -> 6.2880952
A21: 17 | B21: 46052 | C21: 192 | F21: 110 | G21: 200 | H21: 267 | R21: 44224 | AA21: 174 | AB21: 354 | AC21: 177 | AD21: =+IF(B21="","",SUMPRODUCT(C21:AC21,$C$2:$AC$2)) -> 105034 | AE21: =IF(B21="","",C21+F21+H21+K21+Q21+N21+O21+((I21+J21+D21+G21+U21)/2)+(R21/50)+(S21/50)+(T21/50)+(E21/5)) -> 1553.48 | AF21: =IF(B21="","",((AE21*50)/AD21)) -> 0.73951292 | AG21: =IF(C21="","",((Z21)*25)/AD21) -> 0 | AH21: =IF(B21="","",(X21*25)/AD21) -> 0 | AI21: =IF(B21="","",(Y21*25)/AD21) -> 0 | AJ21: =IF(B21="","",(AA21*25)/AD21) -> 0.041415161 | AK21: =IF(B21="","",(AB21*40)/AD21) -> 0.13481349 | AL21: =IF(B21="","",(AC21*50)/AD21) -> 0.084258431 | AM21: =IF(B21="","",B21) -> 46052 | AN21: 23.58 | AO21: 19.1 | AP21: 0.41 | AQ21: =IF(AN21="","",AN21/AO21) -> 1.234555 | AR21: =IF(AN21="","",(AD21/AN21)/1000) -> 4.4543681 | AS21: =IF(AN21="","",AR21*24) -> 106.90483 | AT21: =IF(AN21="","",(AD21/1000)*100%/AS21) -> 0.9825 | AU21: =IF(AN21="","",(AE21/AN21)) -> 65.881255 | AV21: =IF(AN21="","",(AD21/AO21)/1000) -> 5.4991623
AE22: =IF(B22="","",C22+F22+H22+K22+Q22+N22+O22+((I22+J22+D22+G22+U22)/2)+(R22/50)+(S22/50)+(T22/50)+(E22/5)) | AF22: =IF(B22="","",((AE22*50)/AD22)) | AG22: =IF(C22="","",((Z22)*25)/AD22) | AH22: =IF(B22="","",(X22*25)/AD22) | AI22: =IF(B22="","",(Y22*25)/AD22) | AJ22: =IF(B22="","",(AA22*25)/AD22) | AK22: =IF(B22="","",(AB22*40)/AD22) | AL22: =IF(B22="","",(AC22*50)/AD22) | AM22: =IF(B22="","",B22) | AQ22: =IF(AN22="","",AN22/AO22) | AR22: =IF(AN22="","",(AD22/AN22)/1000) | AS22: =IF(AN22="","",AR22*24) | AT22: =IF(AN22="","",(AD22/1000)*100%/AS22) | AU22: =IF(AN22="","",(AE22/AN22)) | AV22: =IF(AN22="","",(AD22/AO22)/1000)
AD23: =IF(B23="","",(((C23+F23+H23+K23+Q23+N23+O23)*50))+((E23*10))+(((I23+J23+D23+G23+L23+M23+U23)*25)+(X23*25)+(Y23*25)+(Z23*25)+(AA23*25)+(AB23*40)+(AC23*50)+(R23*1)+(S23*1)+(T23*1))) | AE23: =IF(B23="","",C23+F23+H23+K23+Q23+N23+O23+((I23+J23+D23+G23+U23)/2)+(R23/50)+(S23/50)+(T23/50)+(E23/5)) | AF23: =IF(B23="","",((AE23*50)/AD23)) | AG23: =IF(C23="","",((Z23)*25)/AD23) | AH23: =IF(B23="","",(X23*25)/AD23) | AI23: =IF(B23="","",(Y23*25)/AD23) | AJ23: =IF(B23="","",(AA23*25)/AD23) | AK23: =IF(B23="","",(AB23*40)/AD23) | AL23: =IF(B23="","",(AC23*50)/AD23) | AM23: =IF(B23="","",B23) | AQ23: =IF(AN23="","",AN23/AO23) | AR23: =IF(AN23="","",(AD23/AN23)/1000) | AS23: =IF(AN23="","",AR23*24) | AT23: =IF(AN23="","",(AD23/1000)*100%/AS23) | AU23: =IF(AN23="","",(AE23/AN23)) | AV23: =IF(AN23="","",(AD23/AO23)/1000)
AE24: =IF(B24="","",C24+F24+H24+K24+Q24+N24+O24+((I24+J24+D24+G24+U24)/2)+(R24/50)+(S24/50)+(T24/50)+(E24/5)) | AF24: =IF(B24="","",((AE24*50)/AD24)) | AG24: =IF(C24="","",((Z24)*25)/AD24) | AH24: =IF(B24="","",(X24*25)/AD24) | AI24: =IF(B24="","",(Y24*25)/AD24) | AJ24: =IF(B24="","",(AA24*25)/AD24) | AK24: =IF(B24="","",(AB24*40)/AD24) | AL24: =IF(B24="","",(AC24*50)/AD24) | AM24: =IF(B24="","",B24) | AQ24: =IF(AN24="","",AN24/AO24) | AR24: =IF(AN24="","",(AD24/AN24)/1000) | AS24: =IF(AN24="","",AR24*24) | AT24: =IF(AN24="","",(AD24/1000)*100%/AS24) | AU24: =IF(AN24="","",(AE24/AN24)) | AV24: =IF(AN24="","",(AD24/AO24)/1000)
A25: =IF(B25="","",1+A24) | AD25: =IF(B25="","",(((C25+F25+H25+K25+Q25+N25+O25)*50))+((E25*10))+(((I25+J25+D25+G25+L25+M25+U25)*25)+(X25*25)+(Y25*25)+(Z25*25)+(AA25*25)+(AB25*40)+(AC25*50)+(R25*1)+(S25*1)+(T25*1))) | AE25: =IF(B25="","",C25+F25+H25+K25+Q25+N25+O25+((I25+J25+D25+G25+U25)/2)+(R25/50)+(S25/50)+(T25/50)+(E25/5)) | AF25: =IF(B25="","",((AE25*50)/AD25)) | AG25: =IF(C25="","",((Z25)*25)/AD25) | AH25: =IF(B25="","",(X25*25)/AD25) | AI25: =IF(B25="","",(Y25*25)/AD25) | AJ25: =IF(B25="","",(AA25*25)/AD25) | AK25: =IF(B25="","",(AB25*40)/AD25) | AL25: =IF(B25="","",(AC25*50)/AD25) | AM25: =IF(B25="","",B25) | AQ25: =IF(AN25="","",AN25/AO25) | AR25: =IF(AN25="","",(AD25/AN25)/1000) | AS25: =IF(AN25="","",AR25*24) | AT25: =IF(AN25="","",(AD25/1000)*100%/AS25) | AU25: =IF(AN25="","",(AE25/AN25)) | AV25: =IF(AN25="","",(AD25/AO25)/1000)
AD26: =IF(B26="","",(((C26+F26+H26+K26+Q26+N26+O26)*50))+((E26*10))+(((I26+J26+D26+G26+L26+M26+U26)*25)+(X26*25)+(Y26*25)+(Z26*25)+(AA26*25)+(AB26*40)+(AC26*50)+(R26*1)+(S26*1)+(T26*1))) | AE26: =IF(B26="","",C26+F26+H26+K26+Q26+N26+O26+((I26+J26+D26+G26+U26)/2)+(R26/50)+(S26/50)+(T26/50)+(E26/5)) | AF26: =IF(B26="","",((AE26*50)/AD26)) | AG26: =IF(C26="","",((Z26)*25)/AD26) | AH26: =IF(B26="","",(X26*25)/AD26) | AI26: =IF(B26="","",(Y26*25)/AD26) | AJ26: =IF(B26="","",(AA26*25)/AD26) | AK26: =IF(B26="","",(AB26*40)/AD26) | AL26: =IF(B26="","",(AC26*50)/AD26) | AM26: =IF(B26="","",B26) | AQ26: =IF(AN26="","",AN26/AO26) | AR26: =IF(AN26="","",(AD26/AN26)/1000) | AS26: =IF(AN26="","",AR26*24) | AT26: =IF(AN26="","",(AD26/1000)*100%/AS26) | AU26: =IF(AN26="","",(AE26/AN26)) | AV26: =IF(AN26="","",(AD26/AO26)/1000)
AD27: =IF(B27="","",(((C27+F27+H27+K27+Q27+N27+O27)*50))+((E27*10))+(((I27+J27+D27+G27+L27+M27+U27)*25)+(X27*25)+(Y27*25)+(Z27*25)+(AA27*25)+(AB27*40)+(AC27*50)+(R27*1)+(S27*1)+(T27*1))) | AE27: =IF(B27="","",C27+F27+H27+K27+Q27+N27+O27+((I27+J27+D27+G27+U27)/2)+(R27/50)+(S27/50)+(T27/50)+(E27/5)) | AF27: =IF(B27="","",((AE27*50)/AD27)) | AG27: =IF(C27="","",((Z27)*25)/AD27) | AH27: =IF(B27="","",(X27*25)/AD27) | AI27: =IF(B27="","",(Y27*25)/AD27) | AJ27: =IF(B27="","",(AA27*25)/AD27) | AK27: =IF(B27="","",(AB27*40)/AD27) | AL27: =IF(B27="","",(AC27*50)/AD27) | AM27: =IF(B27="","",B27) | AQ27: =IF(AN27="","",AN27/AO27) | AR27: =IF(AN27="","",(AD27/AN27)/1000) | AS27: =IF(AN27="","",AR27*24) | AT27: =IF(AN27="","",(AD27/1000)*100%/AS27) | AU27: =IF(AN27="","",(AE27/AN27)) | AV27: =IF(AN27="","",(AD27/AO27)/1000)
AD28: =IF(B28="","",(((C28+F28+H28+K28+Q28+N28+O28)*50))+((E28*10))+(((I28+J28+D28+G28+L28+M28+U28)*25)+(X28*25)+(Y28*25)+(Z28*25)+(AA28*25)+(AB28*40)+(AC28*50)+(R28*1)+(S28*1)+(T28*1))) | AE28: =IF(B28="","",C28+F28+H28+K28+Q28+N28+O28+((I28+J28+D28+G28+U28)/2)+(R28/50)+(S28/50)+(T28/50)+(E28/5)) | AF28: =IF(B28="","",((AE28*50)/AD28)) | AG28: =IF(C28="","",((Z28)*25)/AD28) | AH28: =IF(B28="","",(X28*25)/AD28) | AI28: =IF(B28="","",(Y28*25)/AD28) | AJ28: =IF(B28="","",(AA28*25)/AD28) | AK28: =IF(B28="","",(AB28*40)/AD28) | AL28: =IF(B28="","",(AC28*50)/AD28) | AM28: =IF(B28="","",B28) | AQ28: =IF(AN28="","",AN28/AO28) | AR28: =IF(AN28="","",(AD28/AN28)/1000) | AS28: =IF(AN28="","",AR28*24) | AT28: =IF(AN28="","",(AD28/1000)*100%/AS28) | AU28: =IF(AN28="","",(AE28/AN28)) | AV28: =IF(AN28="","",(AD28/AO28)/1000)
AD29: =IF(B29="","",(((C29+F29+H29+K29+Q29+N29+O29)*50))+((E29*10))+(((I29+J29+D29+G29+L29+M29+U29)*25)+(X29*25)+(Y29*25)+(Z29*25)+(AA29*25)+(AB29*40)+(AC29*50)+(R29*1)+(S29*1)+(T29*1))) | AE29: =IF(B29="","",C29+F29+H29+K29+Q29+N29+O29+((I29+J29+D29+G29+U29)/2)+(R29/50)+(S29/50)+(T29/50)+(E29/5)) | AF29: =IF(B29="","",((AE29*50)/AD29)) | AG29: =IF(C29="","",((Z29)*25)/AD29) | AH29: =IF(B29="","",(X29*25)/AD29) | AI29: =IF(B29="","",(Y29*25)/AD29) | AJ29: =IF(B29="","",(AA29*25)/AD29) | AK29: =IF(B29="","",(AB29*40)/AD29) | AL29: =IF(B29="","",(AC29*50)/AD29) | AM29: =IF(B29="","",B29) | AQ29: =IF(AN29="","",AN29/AO29) | AR29: =IF(AN29="","",(AD29/AN29)/1000) | AS29: =IF(AN29="","",AR29*24) | AT29: =IF(AN29="","",(AD29/1000)*100%/AS29) | AU29: =IF(AN29="","",(AE29/AN29)) | AV29: =IF(AN29="","",(AD29/AO29)/1000)
AD30: =IF(B30="","",(((C30+F30+H30+K30+Q30+N30+O30)*50))+((E30*10))+(((I30+J30+D30+G30+L30+M30+U30)*25)+(X30*25)+(Y30*25)+(Z30*25)+(AA30*25)+(AB30*40)+(AC30*50)+(R30*1)+(S30*1)+(T30*1))) | AE30: =IF(B30="","",C30+F30+H30+K30+Q30+N30+O30+((I30+J30+D30+G30+U30)/2)+(R30/50)+(S30/50)+(T30/50)+(E30/5)) | AF30: =IF(B30="","",((AE30*50)/AD30)) | AG30: =IF(C30="","",((Z30)*25)/AD30) | AH30: =IF(B30="","",(X30*25)/AD30) | AI30: =IF(B30="","",(Y30*25)/AD30) | AJ30: =IF(B30="","",(AA30*25)/AD30) | AK30: =IF(B30="","",(AB30*40)/AD30) | AL30: =IF(B30="","",(AC30*50)/AD30) | AM30: =IF(B30="","",B30) | AQ30: =IF(AN30="","",AN30/AO30) | AR30: =IF(AN30="","",(AD30/AN30)/1000) | AS30: =IF(AN30="","",AR30*24) | AT30: =IF(AN30="","",(AD30/1000)*100%/AS30) | AU30: =IF(AN30="","",(AE30/AN30)) | AV30: =IF(AN30="","",(AD30/AO30)/1000)
A31: =IF(B31="","",1+A30) | AD31: =IF(B31="","",(((C31+F31+H31+K31+Q31+N31+O31)*50))+((E31*10))+(((I31+J31+D31+G31+L31+M31+U31)*25)+(X31*25)+(Y31*25)+(Z31*25)+(AA31*25)+(AB31*40)+(AC31*50)+(R31*1)+(S31*1)+(T31*1))) | AE31: =IF(B31="","",C31+F31+H31+K31+Q31+N31+O31+((I31+J31+D31+G31+U31)/2)+(R31/50)+(S31/50)+(T31/50)+(E31/5)) | AF31: =IF(B31="","",((AE31*50)/AD31)) | AG31: =IF(C31="","",((Z31)*25)/AD31) | AH31: =IF(B31="","",(X31*25)/AD31) | AI31: =IF(B31="","",(Y31*25)/AD31) | AJ31: =IF(B31="","",(AA31*25)/AD31) | AK31: =IF(B31="","",(AB31*40)/AD31) | AL31: =IF(B31="","",(AC31*50)/AD31) | AM31: =IF(B31="","",B31) | AQ31: =IF(AN31="","",AN31/AO31) | AR31: =IF(AN31="","",(AD31/AN31)/1000) | AS31: =IF(AN31="","",AR31*24) | AT31: =IF(AN31="","",(AD31/1000)*100%/AS31) | AU31: =IF(AN31="","",(AE31/AN31)) | AV31: =IF(AN31="","",(AD31/AO31)/1000)
A32: =IF(B32="","",1+A31) | AD32: =IF(B32="","",(((C32+F32+H32+K32+Q32+N32+O32)*50))+((E32*10))+(((I32+J32+D32+G32+L32+M32+U32)*25)+(X32*25)+(Y32*25)+(Z32*25)+(AA32*25)+(AB32*40)+(AC32*50)+(R32*1)+(S32*1)+(T32*1))) | AE32: =IF(B32="","",C32+F32+H32+K32+Q32+N32+O32+((I32+J32+D32+G32+U32)/2)+(R32/50)+(S32/50)+(T32/50)+(E32/5)) | AF32: =IF(B32="","",((AE32*50)/AD32)) | AG32: =IF(C32="","",((Z32)*25)/AD32) | AH32: =IF(B32="","",(X32*25)/AD32) | AI32: =IF(B32="","",(Y32*25)/AD32) | AJ32: =IF(B32="","",(AA32*25)/AD32) | AK32: =IF(B32="","",(AB32*40)/AD32) | AL32: =IF(B32="","",(AC32*50)/AD32) | AM32: =IF(B32="","",B32) | AQ32: =IF(AN32="","",AN32/AO32) | AR32: =IF(AN32="","",(AD32/AN32)/1000) | AS32: =IF(AN32="","",AR32*24) | AT32: =IF(AN32="","",(AD32/1000)*100%/AS32) | AU32: =IF(AN32="","",(AE32/AN32)) | AV32: =IF(AN32="","",(AD32/AO32)/1000)
A33: =IF(B33="","",1+A32) | AD33: =IF(B33="","",(((C33+F33+H33+K33+Q33+N33+O33)*50))+((E33*10))+(((I33+J33+D33+G33+L33+M33+U33)*25)+(X33*25)+(Y33*25)+(Z33*25)+(AA33*25)+(AB33*40)+(AC33*50)+(R33*1)+(S33*1)+(T33*1))) | AE33: =IF(B33="","",C33+F33+H33+K33+Q33+N33+O33+((I33+J33+D33+G33+U33)/2)+(R33/50)+(S33/50)+(T33/50)+(E33/5)) | AF33: =IF(B33="","",((AE33*50)/AD33)) | AG33: =IF(C33="","",((Z33)*25)/AD33) | AH33: =IF(B33="","",(X33*25)/AD33) | AI33: =IF(B33="","",(Y33*25)/AD33) | AJ33: =IF(B33="","",(AA33*25)/AD33) | AK33: =IF(B33="","",(AB33*40)/AD33) | AL33: =IF(B33="","",(AC33*50)/AD33) | AM33: =IF(B33="","",B33) | AQ33: =IF(AN33="","",AN33/AO33) | AR33: =IF(AN33="","",(AD33/AN33)/1000) | AS33: =IF(AN33="","",AR33*24) | AT33: =IF(AN33="","",(AD33/1000)*100%/AS33) | AU33: =IF(AN33="","",(AE33/AN33)) | AV33: =IF(AN33="","",(AD33/AO33)/1000)
A34: =IF(B34="","",1+A33) | AD34: =IF(B34="","",(((C34+F34+H34+K34+Q34+N34+O34)*50))+((E34*10))+(((I34+J34+D34+G34+L34+M34+U34)*25)+(X34*25)+(Y34*25)+(Z34*25)+(AA34*25)+(AB34*40)+(AC34*50)+(R34*1)+(S34*1)+(T34*1))) | AE34: =IF(B34="","",C34+F34+H34+K34+Q34+N34+O34+((I34+J34+D34+G34+U34)/2)+(R34/50)+(S34/50)+(T34/50)+(E34/5)) | AF34: =IF(B34="","",((AE34*50)/AD34)) | AG34: =IF(C34="","",((Z34)*25)/AD34) | AH34: =IF(B34="","",(X34*25)/AD34) | AI34: =IF(B34="","",(Y34*25)/AD34) | AJ34: =IF(B34="","",(AA34*25)/AD34) | AK34: =IF(B34="","",(AB34*40)/AD34) | AL34: =IF(B34="","",(AC34*50)/AD34) | AM34: =IF(B34="","",B34) | AQ34: =IF(AN34="","",AN34/AO34) | AR34: =IF(AN34="","",(AD34/AN34)/1000) | AS34: =IF(AN34="","",AR34*24) | AT34: =IF(AN34="","",(AD34/1000)*100%/AS34) | AU34: =IF(AN34="","",(AE34/AN34)) | AV34: =IF(AN34="","",(AD34/AO34)/1000)
A35: =IF(B35="","",1+A34) | AD35: =IF(B35="","",(((C35+F35+H35+K35+Q35+N35+O35)*50))+((E35*10))+(((I35+J35+D35+G35+L35+M35+U35)*25)+(X35*25)+(Y35*25)+(Z35*25)+(AA35*25)+(AB35*40)+(AC35*50)+(R35*1)+(S35*1)+(T35*1))) | AE35: =IF(B35="","",C35+F35+H35+K35+Q35+N35+O35+((I35+J35+D35+G35+U35)/2)+(R35/50)+(S35/50)+(T35/50)+(E35/5)) | AF35: =IF(B35="","",((AE35*50)/AD35)) | AG35: =IF(C35="","",((Z35)*25)/AD35) | AH35: =IF(B35="","",(X35*25)/AD35) | AI35: =IF(B35="","",(Y35*25)/AD35) | AJ35: =IF(B35="","",(AA35*25)/AD35) | AK35: =IF(B35="","",(AB35*40)/AD35) | AL35: =IF(B35="","",(AC35*50)/AD35) | AM35: =IF(B35="","",B35) | AQ35: =IF(AN35="","",AN35/AO35) | AR35: =IF(AN35="","",(AD35/AN35)/1000) | AS35: =IF(AN35="","",AR35*24) | AT35: =IF(AN35="","",(AD35/1000)*100%/AS35) | AU35: =IF(AN35="","",(AE35/AN35)) | AV35: =IF(AN35="","",(AD35/AO35)/1000)
A36: =IF(B36="","",1+A35) | AD36: =IF(B36="","",(((C36+F36+H36+K36+Q36+N36+O36)*50))+((E36*10))+(((I36+J36+D36+G36+L36+M36+U36)*25)+(X36*25)+(Y36*25)+(Z36*25)+(AA36*25)+(AB36*40)+(AC36*50)+(R36*1)+(S36*1)+(T36*1))) | AE36: =IF(B36="","",C36+F36+H36+K36+Q36+N36+O36+((I36+J36+D36+G36+U36)/2)+(R36/50)+(S36/50)+(T36/50)+(E36/5)) | AF36: =IF(B36="","",((AE36*50)/AD36)) | AG36: =IF(C36="","",((Z36)*25)/AD36) | AH36: =IF(B36="","",(X36*25)/AD36) | AI36: =IF(B36="","",(Y36*25)/AD36) | AJ36: =IF(B36="","",(AA36*25)/AD36) | AK36: =IF(B36="","",(AB36*40)/AD36) | AL36: =IF(B36="","",(AC36*50)/AD36) | AM36: =IF(B36="","",B36) | AQ36: =IF(AN36="","",AN36/AO36) | AR36: =IF(AN36="","",(AD36/AN36)/1000) | AS36: =IF(AN36="","",AR36*24) | AT36: =IF(AN36="","",(AD36/1000)*100%/AS36) | AU36: =IF(AN36="","",(AE36/AN36)) | AV36: =IF(AN36="","",(AD36/AO36)/1000)
B37: Total | C37: =SUM(C5:C11) -> 3409 | D37: =SUM(D5:D11) -> 1248 | E37: =SUM(E5:E11) -> 0 | F37: =SUM(F5:F15) -> 495 | G37: =SUM(G5:G15) -> 182 | H37: =SUM(H5:H21) -> 755 | I37: =SUM(I5:I11) -> 1927 | J37: =SUM(J5:J11) -> 80 | K37: =SUM(K5:K36) -> 746 | L37: =SUM(L5:L36) -> 0 | M37: =SUM(M5:M36) -> 0 | N37: =SUM(N5:N36) -> 0 | O37: =SUM(O5:O36) -> 0 | P37: =SUM(P5:P36) -> 0 | Q37: =SUM(Q5:Q36) -> 265 | R37: =SUM(R5:R10) -> 228268 | S37: =SUM(S5:S36) -> 188722 | T37: =SUM(T5:T36) -> 20640 | U37: =SUM(U5:U36) -> 200 | V37: =SUM(V5:V36) -> 0 | W37: =SUM(W5:W36) -> 0 | X37: =SUM(X5:X36) -> 15 | Y37: =SUM(Y5:Y36) -> 85 | Z37: =+SUM(Z5:Z36) -> 378 | AA37: =SUM(AA5:AA36) -> 3075 | AB37: =SUM(AB5:AB36) -> 6751 | AC37: =SUM(AC5:AC36) -> 1865 | AD37: =SUM(AD5:AD36) -> 1994942 | AE37: =SUM(AE5:AE36) -> 30856.54 | AF37: =IF(AD45=0,"",(AE37*50)/AD37) -> 0.77336935 | AG37: =IF(AD45=0,"",(Z37*50)/AD37) -> 0.0094739596 | AH37: =IF(AD45=0,"",(X37*25)/AD37) -> 0.00018797539 | AI37: =IF(AD45=0,"",(Y37*25)/AD37) -> 0.0010651939 | AJ37: =IF(AD45=0,"",(AA37*25)/AD37) -> 0.038534955 | AK37: =IF(AD45=0,"",(AB37*40)/AD37) -> 0.13536233 | AL37: =IF(AD45=0,"",(AC37*50)/AD37) -> 0.046743214 | AM37: Total | AN37: =SUM(AN5:AN36) -> 395.03 | AO37: =SUM(AO5:AO36) -> 309.35 | AP37: =SUM(AP5:AP36) -> 6.51 | AQ37: =IF(AN37=0,"",AN37/AO37) -> 1.2769678 | AR37: =IF(AN37=0,"",(AD37/AN37)/1000) -> 5.0501025 | AS37: =IF(AN37=0,"",AR37*24) -> 121.20246 | AT37: =IF(AN37=0,"",AD45/(AS37*26)) -> 0.6330609 | AU37: =IF(AN37=0,"",(AE37/AN37)) -> 78.11189 | AV37: =IF(AO37=0,"",(AD37/AO37)/1000) -> 6.4488185 | AW37: =SUM(AW5:AW36)/1000 -> 0 | AX37: =SUM(AX5:AX36)/1000 -> 2031.488 | AY37: =SUM(AY5:AY36)/1000 -> 1577.712 | AZ37: =SUM(AZ5) -> 68862 | BA37: =SUM(BA5:BA36) -> 1632 | BB37: =SUM(BB5:BB36) -> 374982 | BC37: =SUM(BC5:BC36)/1000 -> 1540.192 | BD37: =SUM(BD5:BD36)/1000 -> 1.476 | BE37: =SUM(BE5:BE36)/1000 -> 431.952 | BF37: =SUM(BF5:BF36)/1000 -> 245.848
C38: =+SUM(C12:C14) -> 505 | D38: =+SUM(D12:D14) -> 0 | E38: =+SUM(E12:E14) -> 0 | F38: =SUM(F16:F21) -> 773 | G38: =SUM(G16:G21) -> 800 | I38: =+SUM(I12:I35) -> 826 | J38: =+SUM(J12:J35) -> 120 | R38: =SUM(R11:R13) -> 104288
C39: =+SUM(C15:C21) -> 6275 | D39: =+SUM(D15:D21) -> 0 | E39: =+SUM(E15:E21) -> 0 | R39: =+SUM(R14) -> 100080
R40: =+SUM(R15:R18) -> 60880
...

Sheet FEB
B1: Producción | AH1: Extracción | AN1: Indicadores
B2: HARINA EN BULTO | R2: HARINA GRANEL | U2: P. EXP | V2: REPASO | X2: ESPECIAL | AA2: SUBPRODUCTO | AF2: EXTRACION | AN2: HORAS | AQ2: INDICACORES MOLINO | AV2: MOJADORA | AW2: EQUIPOS ELECTRONICOS
A3: Dia | B3: Fecha | C3: Extrapan 50 | D3: Extrapan 25 | E3: Extrapan 10 | F3: Artesanal 50 | G3: Artesanal 25 | H3: Natural 50 | I3: Fuerte 25 | J3: Fuerte exp 25 | K3: Exclusiva 50 | L3: Exclusiva 25 | M3: S. Sal 25 | N3: Harina Tortas y Ponques | O3: Harina Galeras Ligera | P3: H. Manitova | Q3: ESPECIAL 50 | R3: Harina de alta proteina x 1 G | S3: Harina de baja proteina x 1 | T3: ARTESANAL X 1 G | U3: H. espcial x 25 | V3: + Repaso | W3: - Reproceso | X3: Germen 25 | Y3: Semola 25 | Z3: Grano entero 25 | AA3: Salvado 25 | AB3: Mogolla 40 | AC3: Segunda 50 | AD3: Total trigo | AE3: Total Bultos | AF3: Harina | AG3: Grano entero partido | AH3: =X3 -> Germen 25 | AI3: Semola | AJ3: =AA3 -> Salvado 25 | AK3: =AB3 -> Mogolla 40 | AL3: =AC3 -> Segunda 50 | AM3: =B3 -> Fecha | AN3: Molienda | AO3: moje | AP3: Horas varada | AQ3: Molido/ Mojado | AR3: Capacidad TM. hora | AS3: Capacidad TM. Día | AT3: % Utilizado | AU3: Bultos Hora | AV3: capacidad TM. hora | AW3: MYFC | AX3: Bascula Trigo | AY3: Bascula Harina | AZ3: Agua M³ | BA3: Bascula Mejorante A | BB3: Bascula Mejorante B | BC3: Flowbalacer 1 | BD3: Flowbalacer 2 | BE3: Flowbalacer 3 | BF3: Flowbalacer 4
A4: =IF(B4="","",1) -> 1 | B4: 46055 | R4: 85416 | Y4: 20 | AA4: 155 | AB4: 327 | AC4: 129 | AD4: =IF(B4="","",(((C4+F4+H4+K4+Q4+N4+O4)*50))+((E4*10))+(((I4+J4+D4+G4+L4+M4+U4)*25)+(X4*25)+(Y4*25)+(Z4*25)+(AA4*25)+(AB4*40)+(AC4*50)+(R4*1)+(S4*1)+(T4*1))) -> 109321 | AE4: =IF(B4="","",C4+F4+H4+K4+Q4+N4+O4+((I4+J4+D4+G4)/2)+(R4/50)+(S4/50)+(T4/50)+(U4/2)+(E4/5)) -> 1708.32 | AF4: =IF(B4="","",((AE4*50)/AD4)) -> 0.78133204 | AG4: =IF(C4="","",((Z4)*25)/AD4) | AH4: =IF(B4="","",(X4*25)/AD4) -> 0 | AI4: =IF(B4="","",(Y4*25)/AD4) -> 0.0045736867 | AJ4: =IF(B4="","",(AA4*25)/AD4) -> 0.035446072 | AK4: =IF(B4="","",(AB4*40)/AD4) -> 0.11964764 | AL4: =IF(B4="","",(AC4*50)/AD4) -> 0.059000558 | AM4: =IF(B4="","",B4) -> 46055 | AN4: 24 | AO4: 16.62 | AP4: =24-AN4 -> 0 | AQ4: =IF(AN4="","",AN4/AO4) -> 1.4440433 | AR4: =IF(AN4="","",(AD4/AN4)/1000) -> 4.5550417 | AS4: =IF(AN4="","",AR4*24) -> 109.321 | AT4: =IF(AN4="","",(AD4/1000)*100%/AS4) -> 1 | AU4: =IF(AN4="","",(AE4/AN4)) -> 71.18 | AV4: =IF(AN4="","",(AD4/AO4)/1000) -> 6.5776775 | AX4: 2373408 | AY4: 1837104 | AZ4: 69185 | BA4: 580 | BB4: 354434 | BC4: 123963750 | BD4: 5884169 | BE4: 39502680 | BF4: 47025740
A5: =IF(B5="","",1+A4) -> 2 | B5: 46056 | C5: 1009 | I5: 882 | J5: 80 | R5: 16192 | AA5: 153 | AB5: 381 | AC5: 64 | AD5: =IF(B5="","",(((C5+F5+H5+K5+Q5+N5+O5)*50))+((E5*10))+(((I5+J5+D5+G5+L5+M5+U5)*25)+(X5*25)+(Y5*25)+(Z5*25)+(AA5*25)+(AB5*40)+(AC5*50)+(R5*1)+(S5*1)+(T5*1))) -> 112957 | AE5: =IF(B5="","",C5+F5+H5+K5+Q5+N5+O5+((I5+J5+D5+G5)/2)+(R5/50)+(S5/50)+(T5/50)+(U5/2)+(E5/5)) -> 1813.84 | AF5: =IF(B5="","",((AE5*50)/AD5)) -> 0.8028896 | AG5: =IF(C5="","",((Z5)*25)/AD5) -> 0 | AH5: =IF(B5="","",(X5*25)/AD5) -> 0 | AI5: =IF(B5="","",(Y5*25)/AD5) -> 0 | AJ5: =IF(B5="","",(AA5*25)/AD5) -> 0.033862443 | AK5: =IF(B5="","",(AB5*40)/AD5) -> 0.1349186 | AL5: =IF(B5="","",(AC5*50)/AD5) -> 0.028329364 | AM5: =IF(B5="","",B5) -> 46056 | AN5: 23.75 | AO5: 19.12 | AP5: =24-AN5 -> 0.25 | AQ5: =IF(AN5="","",AN5/AO5) -> 1.2421548 | AR5: =IF(AN5="","",(AD5/AN5)/1000) -> 4.7560842 | AS5: =IF(AN5="","",AR5*24) -> 114.14602 | AT5: =IF(AN5="","",(AD5/1000)*100%/AS5) -> 0.98958333 | AU5: =IF(AN5="","",(AE5/AN5)) -> 76.372211 | AV5: =IF(AN5="","",(AD5/AO5)/1000) -> 5.9077929
A6: =IF(B6="","",1+A5) -> 3 | B6: 46057 | C6: 720 | D6: 1542 | E6: 199 | R6: 14128 | AA6: 172 | AB6: 439 | AC6: 49 | AD6: =IF(B6="","",(((C6+F6+H6+K6+Q6+N6+O6)*50))+((E6*10))+(((I6+J6+D6+G6+L6+M6+U6)*25)+(X6*25)+(Y6*25)+(Z6*25)+(AA6*25)+(AB6*40)+(AC6*50)+(R6*1)+(S6*1)+(T6*1))) -> 114978 | AE6: =IF(B6="","",C6+F6+H6+K6+Q6+N6+O6+((I6+J6+D6+G6)/2)+(R6/50)+(S6/50)+(T6/50)+(U6/2)+(E6/5)) -> 1813.36 | AF6: =IF(B6="","",((AE6*50)/AD6)) -> 0.78856825 | AG6: =IF(C6="","",((Z6)*25)/AD6) -> 0 | AH6: =IF(B6="","",(X6*25)/AD6) -> 0 | AI6: =IF(B6="","",(Y6*25)/AD6) -> 0 | AJ6: =IF(B6="","",(AA6*25)/AD6) -> 0.037398459 | AK6: =IF(B6="","",(AB6*40)/AD6) -> 0.15272487 | AL6: =IF(B6="","",(AC6*50)/AD6) -> 0.021308424 | AM6: =IF(B6="","",B6) -> 46057 | AN6: 23.41 | AO6: 14.48 | AP6: =24-AN6 -> 0.59 | AQ6: =IF(AN6="","",AN6/AO6) -> 1.6167127 | AR6: =IF(AN6="","",(AD6/AN6)/1000) -> 4.9114908 | AS6: =IF(AN6="","",AR6*24) -> 117.87578 | AT6: =IF(AN6="","",(AD6/1000)*100%/AS6) -> 0.97541667 | AU6: =IF(AN6="","",(AE6/AN6)) -> 77.460914 | AV6: =IF(AN6="","",(AD6/AO6)/1000) -> 7.9404696
A7: =IF(B7="","",1+A6) -> 4 | B7: 46058 | F7: 490 | H7: 513 | R7: 12144 | S7: 24880 | U7: 200 | AA7: 111 | AB7: 432 | AC7: 159 | AD7: =IF(B7="","",(((C7+F7+H7+K7+Q7+N7+O7)*50))+((E7*10))+(((I7+J7+D7+G7+L7+M7+U7)*25)+(X7*25)+(Y7*25)+(Z7*25)+(AA7*25)+(AB7*40)+(AC7*50)+(R7*1)+(S7*1)+(T7*1))) -> 120179 | AE7: =IF(B7="","",C7+F7+H7+K7+Q7+N7+O7+((I7+J7+D7+G7)/2)+(R7/50)+(S7/50)+(T7/50)+(U7/2)+(E7/5)) -> 1843.48 | AF7: =IF(B7="","",((AE7*50)/AD7)) -> 0.7669726 | AG7: =IF(C7="","",((Z7)*25)/AD7) | AH7: =IF(B7="","",(X7*25)/AD7) -> 0 | AI7: =IF(B7="","",(Y7*25)/AD7) -> 0 | AJ7: =IF(B7="","",(AA7*25)/AD7) -> 0.023090557 | AK7: =IF(B7="","",(AB7*40)/AD7) -> 0.14378552 | AL7: =IF(B7="","",(AC7*50)/AD7) -> 0.066151324 | AM7: =IF(B7="","",B7) -> 46058 | AN7: 24 | AO7: 18.87 | AP7: =24-AN7 -> 0 | AQ7: =IF(AN7="","",AN7/AO7) -> 1.2718601 | AR7: =IF(AN7="","",(AD7/AN7)/1000) -> 5.0074583 | AS7: =IF(AN7="","",AR7*24) -> 120.179 | AT7: =IF(AN7="","",(AD7/1000)*100%/AS7) -> 1 | AU7: =IF(AN7="","",(AE7/AN7)) -> 76.811667 | AV7: =IF(AN7="","",(AD7/AO7)/1000) -> 6.3687864
A8: =IF(B8="","",1+A7) -> 5 | B8: 46059 | R8: 73336 | AA8: 174 | AB8: 329 | AC8: 144 | AD8: =IF(B8="","",(((C8+F8+H8+K8+Q8+N8+O8)*50))+((E8*10))+(((I8+J8+D8+G8+L8+M8+U8)*25)+(X8*25)+(Y8*25)+(Z8*25)+(AA8*25)+(AB8*40)+(AC8*50)+(R8*1)+(S8*1)+(T8*1))) -> 98046 | AE8: =IF(B8="","",C8+F8+H8+K8+Q8+N8+O8+((I8+J8+D8+G8)/2)+(R8/50)+(S8/50)+(T8/50)+(U8/2)+(E8/5)) -> 1466.72 | AF8: =IF(B8="","",((AE8*50)/AD8)) -> 0.74797544 | AG8: =IF(C8="","",((Z8)*25)/AD8) | AH8: =IF(B8="","",(X8*25)/AD8) -> 0 | AI8: =IF(B8="","",(Y8*25)/AD8) -> 0 | AJ8: =IF(B8="","",(AA8*25)/AD8) -> 0.04436693 | AK8: =IF(B8="","",(AB8*40)/AD8) -> 0.13422271 | AL8: =IF(B8="","",(AC8*50)/AD8) -> 0.073434918 | AM8: =IF(B8="","",B8) -> 46059 | AN8: 22.25 | AO8: =4.48+9.25 -> 13.73 | AP8: =24-AN8 -> 1.75 | AQ8: =IF(AN8="","",AN8/AO8) -> 1.620539 | AR8: =IF(AN8="","",(AD8/AN8)/1000) -> 4.4065618 | AS8: =IF(AN8="","",AR8*24) -> 105.75748 | AT8: =IF(AN8="","",(AD8/1000)*100%/AS8) -> 0.92708333 | AU8: =IF(AN8="","",(AE8/AN8)) -> 65.92 | AV8: =IF(AN8="","",(AD8/AO8)/1000) -> 7.1410051
A9: =IF(B9="","",1+A8) -> 6 | B9: 46062 | C9: =281+30 -> 311 | G9: 161 | I9: =92+1248+35+161+415 -> 1951 | T9: 20360 | AA9: =44+30+18+75 -> 167 | AB9: =103+40+67+145 -> 355 | AC9: 12 | AD9: =IF(B9="","",(((C9+F9+H9+K9+Q9+N9+O9)*50))+((E9*10))+(((I9+J9+D9+G9+L9+M9+U9)*25)+(X9*25)+(Y9*25)+(Z9*25)+(AA9*25)+(AB9*40)+(AC9*50)+(R9*1)+(S9*1)+(T9*1))) -> 107685 | AE9: =IF(B9="","",C9+F9+H9+K9+Q9+N9+O9+((I9+J9+D9+G9)/2)+(R9/50)+(S9/50)+(T9/50)+(U9/2)+(E9/5)) -> 1774.2 | AF9: =IF(B9="","",((AE9*50)/AD9)) -> 0.82379161 | AG9: =IF(C9="","",((Z9)*25)/AD9) -> 0 | AH9: =IF(B9="","",(X9*25)/AD9) -> 0 | AI9: =IF(B9="","",(Y9*25)/AD9) -> 0 | AJ9: =IF(B9="","",(AA9*25)/AD9) -> 0.038770488 | AK9: =IF(B9="","",(AB9*40)/AD9) -> 0.13186609 | AL9: =IF(B9="","",(AC9*50)/AD9) -> 0.0055718067 | AM9: =IF(B9="","",B9) -> 46062 | AN9: 24 | AO9: 15.77 | AP9: =24-AN9 -> 0 | AQ9: =IF(AN9="","",AN9/AO9) -> 1.521877 | AR9: =IF(AN9="","",(AD9/AN9)/1000) -> 4.486875 | AS9: =IF(AN9="","",AR9*24) -> 107.685 | AT9: =IF(AN9="","",(AD9/1000)*100%/AS9) -> 1 | AU9: =IF(AN9="","",(AE9/AN9)) -> 73.925 | AV9: =IF(AN9="","",(AD9/AO9)/1000) -> 6.8284718
A10: =IF(B10="","",1+A9) -> 7 | B10: 46063 | C10: =86500/50 -> 1730 | Y10: =17+5+5 -> 27 | AA10: =44+50+59 -> 153 | AB10: =154*2+132 -> 440 | AC10: 70 | AD10: =IF(B10="","",(((C10+F10+H10+K10+Q10+N10+O10)*50))+((E10*10))+(((I10+J10+D10+G10+L10+M10+U10)*25)+(X10*25)+(Y10*25)+(Z10*25)+(AA10*25)+(AB10*40)+(AC10*50)+(R10*1)+(S10*1)+(T10*1))) -> 112100 | AE10: =IF(B10="","",C10+F10+H10+K10+Q10+N10+O10+((I10+J10+D10+G10)/2)+(R10/50)+(S10/50)+(T10/50)+(U10/2)+(E10/5)) -> 1730 | AF10: =IF(B10="","",((AE10*50)/AD10)) -> 0.77163247 | AG10: =IF(C10="","",((Z10)*25)/AD10) -> 0 | AH10: =IF(B10="","",(X10*25)/AD10) -> 0 | AI10: =IF(B10="","",(Y10*25)/AD10) -> 0.0060214095 | AJ10: =IF(B10="","",(AA10*25)/AD10) -> 0.03412132 | AK10: =IF(B10="","",(AB10*40)/AD10) -> 0.15700268 | AL10: =IF(B10="","",(AC10*50)/AD10) -> 0.031222123 | AM10: =IF(B10="","",B10) -> 46063 | AN10: 22.25 | AO10: 18.25 | AP10: =24-AN10 -> 1.75 | AQ10: =IF(AN10="","",AN10/AO10) -> 1.2191781 | AR10: =IF(AN10="","",(AD10/AN10)/1000) -> 5.0382022 | AS10: =IF(AN10="","",AR10*24) -> 120.91685 | AT10: =IF(AN10="","",(AD10/1000)*100%/AS10) -> 0.92708333 | AU10: =IF(AN10="","",(AE10/AN10)) -> 77.752809 | AV10: =IF(AN10="","",(AD10/AO10)/1000) -> 6.1424658
A11: =IF(B11="","",1+A10) -> 8 | B11: 46064 | C11: 1862 | AA11: 160 | AB11: 396 | AC11: 70 | AD11: =IF(B11="","",(((C11+F11+H11+K11+Q11+N11+O11)*50))+((E11*10))+(((I11+J11+D11+G11+L11+M11+U11)*25)+(X11*25)+(Y11*25)+(Z11*25)+(AA11*25)+(AB11*40)+(AC11*50)+(R11*1)+(S11*1)+(T11*1))) -> 116440 | AE11: =IF(B11="","",C11+F11+H11+K11+Q11+N11+O11+((I11+J11+D11+G11)/2)+(R11/50)+(S11/50)+(T11/50)+(U11/2)+(E11/5)) -> 1862 | AF11: =IF(B11="","",((AE11*50)/AD11)) -> 0.79955342 | AG11: =IF(C11="","",((Z11)*25)/AD11) -> 0 | AH11: =IF(B11="","",(X11*25)/AD11) -> 0 | AI11: =IF(B11="","",(Y11*25)/AD11) -> 0 | AJ11: =IF(B11="","",(AA11*25)/AD11) -> 0.034352456 | AK11: =IF(B11="","",(AB11*40)/AD11) -> 0.13603573 | AL11: =IF(B11="","",(AC11*50)/AD11) -> 0.030058399 | AM11: =IF(B11="","",B11) -> 46064 | AN11: 22.5 | AO11: 14.07 | AP11: =24-AN11 -> 1.5 | AQ11: =IF(AN11="","",AN11/AO11) -> 1.5991471 | AR11: =IF(AN11="","",(AD11/AN11)/1000) -> 5.1751111 | AS11: =IF(AN11="","",AR11*24) -> 124.20267 | AT11: =IF(AN11="","",(AD11/1000)*100%/AS11) -> 0.9375 | AU11: =IF(AN11="","",(AE11/AN11)) -> 82.755556 | AV11: =IF(AN11="","",(AD11/AO11)/1000) -> 8.275764
A12: =IF(B12="","",1+A11) -> 9 | B12: 46065 | C12: 149 | R12: 81024 | AA12: 172 | AB12: 385 | AC12: 196 | AD12: =IF(B12="","",(((C12+F12+H12+K12+Q12+N12+O12)*50))+((E12*10))+(((I12+J12+D12+G12+L12+M12+U12)*25)+(X12*25)+(Y12*25)+(Z12*25)+(AA12*25)+(AB12*40)+(AC12*50)+(R12*1)+(S12*1)+(T12*1))) -> 117974 | AE12: =IF(B12="","",C12+F12+H12+K12+Q12+N12+O12+((I12+J12+D12+G12)/2)+(R12/50)+(S12/50)+(T12/50)+(U12/2)+(E12/5)) -> 1769.48 | AF12: =IF(B12="","",((AE12*50)/AD12)) -> 0.7499449 | AG12: =IF(C12="","",((Z12)*25)/AD12) -> 0 | AH12: =IF(B12="","",(X12*25)/AD12) -> 0 | AI12: =IF(B12="","",(Y12*25)/AD12) -> 0 | AJ12: =IF(B12="","",(AA12*25)/AD12) -> 0.036448709 | AK12: =IF(B12="","",(AB12*40)/AD12) -> 0.13053724 | AL12: =IF(B12="","",(AC12*50)/AD12) -> 0.083069151 | AM12: =IF(B12="","",B12) -> 46065 | AN12: 23.3 | AO12: 22.3 | AP12: =24-AN12 -> 0.7 | AQ12: =IF(AN12="","",AN12/AO12) -> 1.044843 | AR12: =IF(AN12="","",(AD12/AN12)/1000) -> 5.0632618 | AS12: =IF(AN12="","",AR12*24) -> 121.51828 | AT12: =IF(AN12="","",(AD12/1000)*100%/AS12) -> 0.97083333 | AU12: =IF(AN12="","",(AE12/AN12)) -> 75.943348 | AV12: =IF(AN12="","",(AD12/AO12)/1000) -> 5.2903139
A13: =IF(B13="","",1+A12) -> 10 | B13: 46066 | R13: 82608 | AA13: 142 | AB13: 366 | AC13: 189 | AD13: =IF(B13="","",(((C13+F13+H13+K13+Q13+N13+O13)*50))+((E13*10))+(((I13+J13+D13+G13+L13+M13+U13)*25)+(X13*25)+(Y13*25)+(Z13*25)+(AA13*25)+(AB13*40)+(AC13*50)+(R13*1)+(S13*1)+(T13*1))) -> 110248 | AE13: =IF(B13="","",C13+F13+H13+K13+Q13+N13+O13+((I13+J13+D13+G13)/2)+(R13/50)+(S13/50)+(T13/50)+(U13/2)+(E13/5)) -> 1652.16 | AF13: =IF(B13="","",((AE13*50)/AD13)) -> 0.7492925 | AG13: =IF(C13="","",((Z13)*25)/AD13) | AH13: =IF(B13="","",(X13*25)/AD13) -> 0 | AI13: =IF(B13="","",(Y13*25)/AD13) -> 0 | AJ13: =IF(B13="","",(AA13*25)/AD13) -> 0.032200131 | AK13: =IF(B13="","",(AB13*40)/AD13) -> 0.13279152 | AL13: =IF(B13="","",(AC13*50)/AD13) -> 0.085715841 | AM13: =IF(B13="","",B13) -> 46066 | AN13: 24 | AO13: =8.43+10.14 -> 18.57 | AP13: =24-AN13 -> 0 | AQ13: =IF(AN13="","",AN13/AO13) -> 1.2924071 | AR13: =IF(AN13="","",(AD13/AN13)/1000) -> 4.5936667 | AS13: =IF(AN13="","",AR13*24) -> 110.248 | AT13: =IF(AN13="","",(AD13/1000)*100%/AS13) -> 1 | AU13: =IF(AN13="","",(AE13/AN13)) -> 68.84 | AV13: =IF(AN13="","",(AD13/AO13)/1000) -> 5.9368875
A14: =IF(B14="","",1+A13) -> 11 | B14: 46069 | R14: =50352+28912+2120+6592 -> 87976 | Y14: =15+23 -> 38 | AA14: =100+63+59 -> 222 | AB14: =150+80+131+125 -> 486 | AC14: =73+40 -> 113 | AD14: =IF(B14="","",(((C14+F14+H14+K14+Q14+N14+O14)*50))+((E14*10))+(((I14+J14+D14+G14+L14+M14+U14)*25)+(X14*25)+(Y14*25)+(Z14*25)+(AA14*25)+(AB14*40)+(AC14*50)+(R14*1)+(S14*1)+(T14*1))) -> 119566 | AE14: =IF(B14="","",C14+F14+H14+K14+Q14+N14+O14+((I14+J14+D14+G14)/2)+(R14/50)+(S14/50)+(T14/50)+(U14/2)+(E14/5)) -> 1759.52 | AF14: =IF(B14="","",((AE14*50)/AD14)) -> 0.73579446 | AG14: =IF(C14="","",((Z14)*25)/AD14) | AH14: =IF(B14="","",(X14*25)/AD14) -> 0 | AI14: =IF(B14="","",(Y14*25)/AD14) -> 0.0079454025 | AJ14: =IF(B14="","",(AA14*25)/AD14) -> 0.046417878 | AK14: =IF(B14="","",(AB14*40)/AD14) -> 0.16258803 | AL14: =IF(B14="","",(AC14*50)/AD14) -> 0.047254236 | AM14: =IF(B14="","",B14) -> 46069 | AN14: 24 | AO14: 20.38 | AP14: =24-AN14 -> 0 | AQ14: =IF(AN14="","",AN14/AO14) -> 1.1776251 | AR14: =IF(AN14="","",(AD14/AN14)/1000) -> 4.9819167 | AS14: =IF(AN14="","",AR14*24) -> 119.566 | AT14: =IF(AN14="","",(AD14/1000)*100%/AS14) -> 1 | AU14: =IF(AN14="","",(AE14/AN14)) -> 73.313333 | AV14: =IF(AN14="","",(AD14/AO14)/1000) -> 5.8668302
A15: =IF(B15="","",1+A14) -> 12 | B15: 46070 | C15: 62 | R15: =14112+30016 -> 44128 | T15: 24400 | Y15: 2 | AA15: =30+59+35 -> 124 | AB15: =66+125+170 -> 361 | AC15: =34+67 -> 101 | AD15: =IF(B15="","",(((C15+F15+H15+K15+Q15+N15+O15)*50))+((E15*10))+(((I15+J15+D15+G15+L15+M15+U15)*25)+(X15*25)+(Y15*25)+(Z15*25)+(AA15*25)+(AB15*40)+(AC15*50)+(R15*1)+(S15*1)+(T15*1))) -> 94268 | AE15: =IF(B15="","",C15+F15+H15+K15+Q15+N15+O15+((I15+J15+D15+G15)/2)+(R15/50)+(S15/50)+(T15/50)+(U15/2)+(E15/5)) -> 1432.56 | AF15: =IF(B15="","",((AE15*50)/AD15)) -> 0.75983367 | AG15: =IF(C15="","",((Z15)*25)/AD15) -> 0 | AH15: =IF(B15="","",(X15*25)/AD15) -> 0 | AI15: =IF(B15="","",(Y15*25)/AD15) -> 0.00053040268 | AJ15: =IF(B15="","",(AA15*25)/AD15) -> 0.032884966 | AK15: =IF(B15="","",(AB15*40)/AD15) -> 0.15318029 | AL15: =IF(B15="","",(AC15*50)/AD15) -> 0.053570671 | AM15: =IF(B15="","",B15) -> 46070 | AN15: 23.41 | AO15: 14.22 | AP15: =24-AN15 -> 0.59 | AQ15: =IF(AN15="","",AN15/AO15) -> 1.6462729 | AR15: =IF(AN15="","",(AD15/AN15)/1000) -> 4.0268261 | AS15: =IF(AN15="","",AR15*24) -> 96.643827 | AT15: =IF(AN15="","",(AD15/1000)*100%/AS15) -> 0.97541667 | AU15: =IF(AN15="","",(AE15/AN15)) -> 61.194361 | AV15: =IF(AN15="","",(AD15/AO15)/1000) -> 6.6292546
A16: =IF(B16="","",1+A15) -> 13 | B16: 46071 | C16: =68+568+210+426+355+271 -> 1898 | AA16: =59+61 -> 120 | AB16: =135+132+123 -> 390 | AC16: 56 | AD16: =IF(B16="","",(((C16+F16+H16+K16+Q16+N16+O16)*50))+((E16*10))+(((I16+J16+D16+G16+L16+M16+U16)*25)+(X16*25)+(Y16*25)+(Z16*25)+(AA16*25)+(AB16*40)+(AC16*50)+(R16*1)+(S16*1)+(T16*1))) -> 116300 | AE16: =IF(B16="","",C16+F16+H16+K16+Q16+N16+O16+((I16+J16+D16+G16)/2)+(R16/50)+(S16/50)+(T16/50)+(U16/2)+(E16/5)) -> 1898 | AF16: =IF(B16="","",((AE16*50)/AD16)) -> 0.81599312 | AG16: =IF(C16="","",((Z16)*25)/AD16) -> 0 | AH16: =IF(B16="","",(X16*25)/AD16) -> 0 | AI16: =IF(B16="","",(Y16*25)/AD16) -> 0 | AJ16: =IF(B16="","",(AA16*25)/AD16) -> 0.025795357 | AK16: =IF(B16="","",(AB16*40)/AD16) -> 0.13413586 | AL16: =IF(B16="","",(AC16*50)/AD16) -> 0.024075666 | AM16: =IF(B16="","",B16) -> 46071 | AN16: 23.83 | AO16: 13.87 | AP16: =24-AN16 -> 0.17 | AQ16: =IF(AN16="","",AN16/AO16) -> 1.7180966 | AR16: =IF(AN16="","",(AD16/AN16)/1000) -> 4.8804029 | AS16: =IF(AN16="","",AR16*24) -> 117.12967 | AT16: =IF(AN16="","",(AD16/1000)*100%/AS16) -> 0.99291667 | AU16: =IF(AN16="","",(AE16/AN16)) -> 79.647503 | AV16: =IF(AN16="","",(AD16/AO16)/1000) -> 8.3850036
A17: =IF(B17="","",1+A16) -> 14 | B17: 46072 | C17: =509+117+474 -> 1100 | R17: =6912+29024 -> 35936 | AA17: =90+84+62 -> 236 | AB17: =63+167+134 -> 364 | AC17: 130 | AD17: =IF(B17="","",(((C17+F17+H17+K17+Q17+N17+O17)*50))+((E17*10))+(((I17+J17+D17+G17+L17+M17+U17)*25)+(X17*25)+(Y17*25)+(Z17*25)+(AA17*25)+(AB17*40)+(AC17*50)+(R17*1)+(S17*1)+(T17*1))) -> 117896 | AE17: =IF(B17="","",C17+F17+H17+K17+Q17+N17+O17+((I17+J17+D17+G17)/2)+(R17/50)+(S17/50)+(T17/50)+(U17/2)+(E17/5)) -> 1818.72 | AF17: =IF(B17="","",((AE17*50)/AD17)) -> 0.77132388 | AG17: =IF(C17="","",((Z17)*25)/AD17) -> 0 | AH17: =IF(B17="","",(X17*25)/AD17) -> 0 | AI17: =IF(B17="","",(Y17*25)/AD17) -> 0 | AJ17: =IF(B17="","",(AA17*25)/AD17) -> 0.050044107 | AK17: =IF(B17="","",(AB17*40)/AD17) -> 0.12349868 | AL17: =IF(B17="","",(AC17*50)/AD17) -> 0.055133338 | AM17: =IF(B17="","",B17) -> 46072 | AN17: 19.58 | AO17: 14.72 | AP17: =24-AN17 -> 4.42 | AQ17: =IF(AN17="","",AN17/AO17) -> 1.330163 | AR17: =IF(AN17="","",(AD17/AN17)/1000) -> 6.0212462 | AS17: =IF(AN17="","",AR17*24) -> 144.50991 | AT17: =IF(AN17="","",(AD17/1000)*100%/AS17) -> 0.81583333 | AU17: =IF(AN17="","",(AE17/AN17)) -> 92.886619 | AV17: =IF(AN17="","",(AD17/AO17)/1000) -> 8.0092391
A18: =IF(B18="","",1+A17) -> 15 | B18: 46073 | R18: =24656+15024 -> 39680 | S18: =9296+39984 -> 49280 | AA18: 163 | AB18: =118+110+246 -> 474 | AC18: =42+11+88 -> 141 | AD18: =IF(B18="","",(((C18+F18+H18+K18+Q18+N18+O18)*50))+((E18*10))+(((I18+J18+D18+G18+L18+M18+U18)*25)+(X18*25)+(Y18*25)+(Z18*25)+(AA18*25)+(AB18*40)+(AC18*50)+(R18*1)+(S18*1)+(T18*1))) -> 119045 | AE18: =IF(B18="","",C18+F18+H18+K18+Q18+N18+O18+((I18+J18+D18+G18)/2)+(R18/50)+(S18/50)+(T18/50)+(U18/2)+(E18/5)) -> 1779.2 | AF18: =IF(B18="","",((AE18*50)/AD18)) -> 0.74728044 | AG18: =IF(C18="","",((Z18)*25)/AD18) | AH18: =IF(B18="","",(X18*25)/AD18) -> 0 | AI18: =IF(B18="","",(Y18*25)/AD18) -> 0 | AJ18: =IF(B18="","",(AA18*25)/AD18) -> 0.034230753 | AK18: =IF(B18="","",(AB18*40)/AD18) -> 0.1592675 | AL18: =IF(B18="","",(AC18*50)/AD18) -> 0.059221303 | AM18: =IF(B18="","",B18) -> 46073 | AN18: 24 | AO18: =9.17+9.65 -> 18.82 | AP18: =24-AN18 -> 0 | AQ18: =IF(AN18="","",AN18/AO18) -> 1.2752391 | AR18: =IF(AN18="","",(AD18/AN18)/1000) -> 4.9602083 | AS18: =IF(AN18="","",AR18*24) -> 119.045 | AT18: =IF(AN18="","",(AD18/1000)*100%/AS18) -> 1 | AU18: =IF(AN18="","",(AE18/AN18)) -> 74.133333 | AV18: =IF(AN18="","",(AD18/AO18)/1000) -> 6.3254516
A19: =IF(B19="","",1+A18) -> 16 | B19: 46075 | R19: 55504 | AA19: 92 | AB19: 245 | AC19: 0 | AD19: =IF(B19="","",(((C19+F19+H19+K19+Q19+N19+O19)*50))+((E19*10))+(((I19+J19+D19+G19+L19+M19+U19)*25)+(X19*25)+(Y19*25)+(Z19*25)+(AA19*25)+(AB19*40)+(AC19*50)+(R19*1)+(S19*1)+(T19*1))) -> 67604 | AE19: =IF(B19="","",C19+F19+H19+K19+Q19+N19+O19+((I19+J19+D19+G19)/2)+(R19/50)+(S19/50)+(T19/50)+(U19/2)+(E19/5)) -> 1110.08 | AF19: =IF(B19="","",((AE19*50)/AD19)) -> 0.82101651 | AG19: =IF(C19="","",((Z19)*25)/AD19) | AH19: =IF(B19="","",(X19*25)/AD19) -> 0 | AI19: =IF(B19="","",(Y19*25)/AD19) -> 0 | AJ19: =IF(B19="","",(AA19*25)/AD19) -> 0.034021656 | AK19: =IF(B19="","",(AB19*40)/AD19) -> 0.14496184 | AL19: =IF(B19="","",(AC19*50)/AD19) -> 0 | AM19: =IF(B19="","",B19) -> 46075 | AN19: 24 | AO19: 15.7 | AP19: =24-AN19 -> 0 | AQ19: =IF(AN19="","",AN19/AO19) -> 1.5286624 | AR19: =IF(AN19="","",(AD19/AN19)/1000) -> 2.8168333 | AS19: =IF(AN19="","",AR19*24) -> 67.604 | AT19: =IF(AN19="","",(AD19/1000)*100%/AS19) -> 1 | AU19: =IF(AN19="","",(AE19/AN19)) -> 46.253333 | AV19: =IF(AN19="","",(AD19/AO19)/1000) -> 4.3059873
A20: =IF(B20="","",1+A19) -> 17 | B20: 46076 | I20: =320+880+85+584 -> 1869 | R20: 35760 | U20: 275 | AA20: =55+25+77 -> 157 | AB20: =134+126+147 -> 407 | AC20: 173 | AD20: =IF(B20="","",(((C20+F20+H20+K20+Q20+N20+O20)*50))+((E20*10))+(((I20+J20+D20+G20+L20+M20+U20)*25)+(X20*25)+(Y20*25)+(Z20*25)+(AA20*25)+(AB20*40)+(AC20*50)+(R20*1)+(S20*1)+(T20*1))) -> 118215 | AE20: =IF(B20="","",C20+F20+H20+K20+Q20+N20+O20+((I20+J20+D20+G20+U20)/2)+(R20/50)+(S20/50)+(T20/50)+(E20/5)) -> 1787.2 | AF20: =IF(B20="","",((AE20*50)/AD20)) -> 0.75591084 | AG20: =IF(C20="","",((Z20)*25)/AD20) | AH20: =IF(B20="","",(X20*25)/AD20) -> 0 | AI20: =IF(B20="","",(Y20*25)/AD20) -> 0 | AJ20: =IF(B20="","",(AA20*25)/AD20) -> 0.033202216 | AK20: =IF(B20="","",(AB20*40)/AD20) -> 0.13771518 | AL20: =IF(B20="","",(AC20*50)/AD20) -> 0.073171763 | AM20: =IF(B20="","",B20) -> 46076 | AN20: 21.83 | AO20: 20.98 | AP20: =24-AN20 -> 2.17 | AQ20: =IF(AN20="","",AN20/AO20) -> 1.0405148 | AR20: =IF(AN20="","",(AD20/AN20)/1000) -> 5.4152542 | AS20: =IF(AN20="","",AR20*24) -> 129.9661 | AT20: =IF(AN20="","",(AD20/1000)*100%/AS20) -> 0.90958333 | AU20: =IF(AN20="","",(AE20/AN20)) -> 81.868988 | AV20: =IF(AN20="","",(AD20/AO20)/1000) -> 5.634652
A21: =IF(B21="","",1+A20) -> 18 | B21: 46077 | I21: 40 | R21: 86766 | AA21: =4550/25 -> 182 | AB21: =14880/40 -> 372 | AC21: =5200/50 -> 104 | AD21: =IF(B21="","",(((C21+F21+H21+K21+Q21+N21+O21)*50))+((E21*10))+(((I21+J21+D21+G21+L21+M21+U21)*25)+(X21*25)+(Y21*25)+(Z21*25)+(AA21*25)+(AB21*40)+(AC21*50)+(R21*1)+(S21*1)+(T21*1))) -> 112396 | AE21: =IF(B21="","",C21+F21+H21+K21+Q21+N21+O21+((I21+J21+D21+G21+U21)/2)+(R21/50)+(S21/50)+(T21/50)+(E21/5)) -> 1755.32 | AF21: =IF(B21="","",((AE21*50)/AD21)) -> 0.78086409 | AG21: =IF(C21="","",((Z21)*25)/AD21) | AH21: =IF(B21="","",(X21*25)/AD21) -> 0 | AI21: =IF(B21="","",(Y21*25)/AD21) -> 0 | AJ21: =IF(B21="","",(AA21*25)/AD21) -> 0.040481868 | AK21: =IF(B21="","",(AB21*40)/AD21) -> 0.13238905 | AL21: =IF(B21="","",(AC21*50)/AD21) -> 0.046264992 | AM21: =IF(B21="","",B21) -> 46077 | AN21: 24 | AO21: 14.38 | AP21: =24-AN21 -> 0 | AQ21: =IF(AN21="","",AN21/AO21) -> 1.6689847 | AR21: =IF(AN21="","",(AD21/AN21)/1000) -> 4.6831667 | AS21: =IF(AN21="","",AR21*24) -> 112.396 | AT21: =IF(AN21="","",(AD21/1000)*100%/AS21) -> 1 | AU21: =IF(AN21="","",(AE21/AN21)) -> 73.138333 | AV21: =IF(AN21="","",(AD21/AO21)/1000) -> 7.8161335
A22: =IF(B22="","",1+A21) -> 19 | B22: 46078 | C22: =46100/50 -> 922 | F22: =115+250 -> 365 | G22: =39+198 -> 237 | I22: =96+871 -> 967 | AA22: =52+60+47 -> 159 | AB22: =135+126+126 -> 387 | AC22: =18+35 -> 53 | AD22: =IF(B22="","",(((C22+F22+H22+K22+Q22+N22+O22)*50))+((E22*10))+(((I22+J22+D22+G22+L22+M22+U22)*25)+(X22*25)+(Y22*25)+(Z22*25)+(AA22*25)+(AB22*40)+(AC22*50)+(R22*1)+(S22*1)+(T22*1))) -> 116555 | AE22: =IF(B22="","",C22+F22+H22+K22+Q22+N22+O22+((I22+J22+D22+G22+U22)/2)+(R22/50)+(S22/50)+(T22/50)+(E22/5)) -> 1889 | AF22: =IF(B22="","",((AE22*50)/AD22)) -> 0.81034705 | AG22: =IF(C22="","",((Z22)*25)/AD22) -> 0 | AH22: =IF(B22="","",(X22*25)/AD22) -> 0 | AI22: =IF(B22="","",(Y22*25)/AD22) -> 0 | AJ22: =IF(B22="","",(AA22*25)/AD22) -> 0.034104071 | AK22: =IF(B22="","",(AB22*40)/AD22) -> 0.13281284 | AL22: =IF(B22="","",(AC22*50)/AD22) -> 0.022736047 | AM22: =IF(B22="","",B22) -> 46078 | AN22: 24 | AO22: 16.92 | AP22: =24-AN22 -> 0 | AQ22: =IF(AN22="","",AN22/AO22) -> 1.4184397 | AR22: =IF(AN22="","",(AD22/AN22)/1000) -> 4.8564583 | AS22: =IF(AN22="","",AR22*24) -> 116.555 | AT22: =IF(AN22="","",(AD22/1000)*100%/AS22) -> 1 | AU22: =IF(AN22="","",(AE22/AN22)) -> 78.708333 | AV22: =IF(AN22="","",(AD22/AO22)/1000) -> 6.8885934
A23: =IF(B23="","",1+A22) -> 20 | B23: 46079 | C23: =68+45 -> 113 | I23: =35+983 -> 1018 | R23: 31424 | S23: 25536 | AA23: =48+71+62 -> 181 | AB23: =160+176+134 -> 470 | AC23: =11+90 -> 101 | AD23: =IF(B23="","",(((C23+F23+H23+K23+Q23+N23+O23)*50))+((E23*10))+(((I23+J23+D23+G23+L23+M23+U23)*25)+(X23*25)+(Y23*25)+(Z23*25)+(AA23*25)+(AB23*40)+(AC23*50)+(R23*1)+(S23*1)+(T23*1))) -> 116435 | AE23: =IF(B23="","",C23+F23+H23+K23+Q23+N23+O23+((I23+J23+D23+G23+U23)/2)+(R23/50)+(S23/50)+(T23/50)+(E23/5)) -> 1761.2 | AF23: =IF(B23="","",((AE23*50)/AD23)) -> 0.7563018 | AG23: =IF(C23="","",((Z23)*25)/AD23) -> 0 | AH23: =IF(B23="","",(X23*25)/AD23) -> 0 | AI23: =IF(B23="","",(Y23*25)/AD23) -> 0 | AJ23: =IF(B23="","",(AA23*25)/AD23) -> 0.038862885 | AK23: =IF(B23="","",(AB23*40)/AD23) -> 0.16146348 | AL23: =IF(B23="","",(AC23*50)/AD23) -> 0.043371838 | AM23: =IF(B23="","",B23) -> 46079 | AN23: 24 | AO23: =9.8+9.48 -> 19.28 | AP23: =24-AN23 -> 0 | AQ23: =IF(AN23="","",AN23/AO23) -> 1.2448133 | AR23: =IF(AN23="","",(AD23/AN23)/1000) -> 4.8514583 | AS23: =IF(AN23="","",AR23*24) -> 116.435 | AT23: =IF(AN23="","",(AD23/1000)*100%/AS23) -> 1 | AU23: =IF(AN23="","",(AE23/AN23)) -> 73.383333 | AV23: =IF(AN23="","",(AD23/AO23)/1000) -> 6.0391598
